Workbook

Sheet Dashboard
A1: Paste here your ID (A2 EDIT) | B1: Ranking | E1: Scan name | F1: Scan date | G1: Power | H1: Kill Points | I1: Deads | J1: T4 Kills | K1: T5 Kills | L1: T4 Deads | M1: T5 Deads | N1: RSS Assist
A2: 171604682 | B2: =VLOOKUP(A2,'Kings Land Report'!A:Y,24,FALSE) & " /178" -> 15 /178 | E2: BASE SCAN | F2: 46002 | G2: =VLOOKUP(A2,SoC_Data!A:K,10,FALSE) -> 72662012 | H2: =VLOOKUP(A2,SoC_Data!A:K,11,FALSE) -> 1073587588 | I2: =VLOOKUP(A2,SoC_Data!A:K,8,FALSE) -> 5696214 | J2: =VLOOKUP(A2,SoC_Data!A:K,6,FALSE) -> 43131336 | K2: =VLOOKUP(A2,SoC_Data!A:K,7,FALSE) -> 30009811 | L2: X | M2: X | N2: =VLOOKUP(A2,SoC_Data!A:K,9,FALSE) -> 1370720264
A3: Player Name | C3: =VLOOKUP(A2,SoC_Data!A:D,2,FALSE) -> ᵁᴺDaddyツ | E3: Lvl 4 Pass Scan | F3: 46006 | G3: =VLOOKUP(A2,SoC_Data!A:R,17,FALSE)-VLOOKUP(A2,SoC_Data!A:R,10,FALSE) -> -2574394 | H3: =VLOOKUP(A2,SoC_Data!A:R,18,FALSE)-VLOOKUP(A2,SoC_Data!A:R,11,FALSE) -> 62968823 | I3: =VLOOKUP(A2,SoC_Data!A:R,15,FALSE)-VLOOKUP(A2,SoC_Data!A:R,8,FALSE) -> 308388 | J3: =VLOOKUP(A2,SoC_Data!A:R,13,FALSE)-VLOOKUP(A2,SoC_Data!A:R,6,FALSE) -> 1490994 | K3: =VLOOKUP(A2,SoC_Data!A:R,14,FALSE)-VLOOKUP(A2,SoC_Data!A:R,7,FALSE) -> 2399566 | L3: X | M3: X | N3: =VLOOKUP(A2,SoC_Data!A:R,16,FALSE)-VLOOKUP(A2,SoC_Data!A:R,9,FALSE) -> 0
A4: DKP Minimal requirement | C4: =VLOOKUP(A2,BS_Report!A:P,7,FALSE) -> 32697905 | E4: Altar P1 Scan | F4: 46013 | G4: =VLOOKUP(A2,SoC_Data!A:AF,31,FALSE)-VLOOKUP(A2,SoC_Data!A:AF,24,FALSE) -> 83450 | H4: =VLOOKUP(A2,SoC_Data!A:AF,32,FALSE)-VLOOKUP(A2,SoC_Data!A:AF,25,FALSE) -> 10934640 | I4: =VLOOKUP(A2,SoC_Data!A:AF,29,FALSE)-VLOOKUP(A2,SoC_Data!A:AF,22,FALSE) -> 0 | J4: =VLOOKUP(A2,SoC_Data!A:AF,27,FALSE)-VLOOKUP(A2,SoC_Data!A:AF,20,FALSE) -> 355390 | K4: =VLOOKUP(A2,SoC_Data!A:AF,28,FALSE)-VLOOKUP(A2,SoC_Data!A:AF,21,FALSE) -> 369037 | L4: X | M4: X | N4: =VLOOKUP(A2,SoC_Data!A:AF,30,FALSE)-VLOOKUP(A2,SoC_Data!A:AF,23,FALSE) -> 0
A5: KP Minimal Requirement | C5: =VLOOKUP(A2,BS_Report!A:P,5,FALSE) -> 1.9947882e+08 | E5: Pass 7 Scan | F5: 46021 | G5: =VLOOKUP(A2,SoC_Data!A:AM,38,FALSE)-VLOOKUP(A2,SoC_Data!A:AM,31,FALSE) -> -7836806 | H5: =VLOOKUP(A2,SoC_Data!A:AM,39,FALSE)-VLOOKUP(A2,SoC_Data!A:AM,32,FALSE) -> 117522708 | I5: =VLOOKUP(A2,SoC_Data!A:AM,36,FALSE)-VLOOKUP(A2,SoC_Data!A:AM,29,FALSE) -> 406784 | J5: =VLOOKUP(A2,SoC_Data!A:AM,34,FALSE)-VLOOKUP(A2,SoC_Data!A:AM,27,FALSE) -> 967808 | K5: =VLOOKUP(A2,SoC_Data!A:AM,35,FALSE)-VLOOKUP(A2,SoC_Data!A:AM,28,FALSE) -> 5391768 | L5: X | M5: X | N5: =VLOOKUP(A2,SoC_Data!A:AM,37,FALSE)-VLOOKUP(A2,SoC_Data!A:AM,30,FALSE) -> 150000000
A6: Dead Minimal Requirement | C6: =VLOOKUP(A2,BS_Report!A:P,6,FALSE) -> 1.0681135e+08 | E6: Mid Review Scan | F6: 46028 | G6: =VLOOKUP(A2,SoC_Data!A:AT,45,FALSE)-VLOOKUP(A2,SoC_Data!A:AT,38,FALSE) -> 4951430 | H6: =VLOOKUP(A2,SoC_Data!A:AT,46,FALSE)-VLOOKUP(A2,SoC_Data!A:AT,39,FALSE) -> 19009960 | I6: =VLOOKUP(A2,SoC_Data!A:AT,43,FALSE)-VLOOKUP(A2,SoC_Data!A:AT,36,FALSE) -> 14671 | J6: =VLOOKUP(A2,SoC_Data!A:AT,41,FALSE)-VLOOKUP(A2,SoC_Data!A:AT,34,FALSE) -> 671324 | K6: =VLOOKUP(A2,SoC_Data!A:AT,42,FALSE)-VLOOKUP(A2,SoC_Data!A:AT,35,FALSE) -> 614836 | L6: X | M6: X | N6: =VLOOKUP(A2,SoC_Data!A:AT,44,FALSE)-VLOOKUP(A2,SoC_Data!A:AT,37,FALSE) -> 0
A7: Tier 4 Kills | B7: X | C7: =J12 -> 4272984 | E7: Kings Land Scan | F7: 46032 | G7: =VLOOKUP(A2,SoC_Data!A:BA,52,FALSE)-VLOOKUP(A2,SoC_Data!A:BA,45,FALSE) -> -3138156 | H7: =VLOOKUP(A2,SoC_Data!A:BA,53,FALSE)-VLOOKUP(A2,SoC_Data!A:BA,46,FALSE) -> 65611255 | I7: =VLOOKUP(A2,SoC_Data!A:BA,50,FALSE)-VLOOKUP(A2,SoC_Data!A:BA,43,FALSE) -> 171865 | J7: =VLOOKUP(A2,SoC_Data!A:BA,48,FALSE)-VLOOKUP(A2,SoC_Data!A:BA,41,FALSE) -> 787468 | K7: =VLOOKUP(A2,SoC_Data!A:BA,49,FALSE)-VLOOKUP(A2,SoC_Data!A:BA,42,FALSE) -> 2885915 | L7: =IFERROR(VLOOKUP(A2,'Kings Land Report'!A:Y,16,FALSE) / 100, "TBA") -> 233 | M7: =IFERROR(VLOOKUP(A2,'Kings Land Report'!A:Y,17,FALSE) / 200, "TBA") -> 901475 | N7: =VLOOKUP(A2,SoC_Data!A:BA,51,FALSE)-VLOOKUP(A2,SoC_Data!A:BA,44,FALSE) -> 60000000
A8: Tier 5 Kills | B8: X | C8: =K12 -> 11661122 | L8: X | M8: X
A9: Tier 4 Deads | B9: X | C9: =L12 -> 233 | L9: X | M9: X
A10: Tier 5 Deads | B10: X | C10: =M12 -> 901475 | L10: X | M10: X
A11: KP Gained | B11: X | C11: =SUM(H3:H7) -> 276047386 | O11: TOTAL DKP
A12: Total DKP | B12: X | C12: =O12 -> 147228776 | E12: DKP SUMMARY | F12: X | G12: =SUM(G2:G9) -> 64147536 | H12: =SUM(H2:H9) -> 1349634974 | I12: =SUM(I3:I9) -> 901708 | J12: =SUM(J3:J9) -> 4272984 | K12: =SUM(K3:K9) -> 11661122 | L12: =SUM(L3:L8) -> 233 | M12: =SUM(M3:M8) -> 901475 | N12: =SUM(N3:N9) -> 210000000 | O12: =SUM(J12*4,K12*10,I12*15) -> 147228776
A15: How to use? 1. Copy your profile ID 2. Paste it in A2 Slot 3. Click Enter | E15: KINGDOM STATISTICS
A18: DKP STATUS HISTORY | E18: Scan name | F18: Scan date | G18: Power | H18: Kill Points | I18: Deads | J18: T4 Kills | K18: T5 Kills | L18: T4 Deads | M18: T5 Deads | N18: RSS Assist
A19: Excellent | B19: >25% | C19: (~˘▾˘)~ | E19: BS (TOP300) | F19: 46002 | G19: 11180721781 | H19: 129539827144 | I19: 1528281834 | J19: 4716942816 | K19: 3989450552 | N19: 1371005637679
A20: Normal | B20: 15-25% | C20: ¯\_(ツ)_/¯ | E20: Lvl 4 Pass(TOP300) | F20: 46006 | G20: 10867057311 | H20: 133580316573 | I20: 1548613371 | J20: 4743167081 | K20: 4177164400 | L20: =4178440+3240903+3969058+332751 -> 11721152 | M20: =4538885+4412093+5445812+20607 -> 14417397 | N20: 1374318532907
A21: Deadweight | B21: <15% | C21: (ʘᗩʘ') | E21: Altar P1(TOP300) | F21: 46013 | G21: 10913196282 | H21: 133185732701 | I21: 1520651081 | J21: 4720355259 | K21: 4169143435 | L21: =4267301+3310183+4040258+332751 -> 11950493 | M21: =4596214+4527956+5469434+20607 -> 14614211 | N21: 1351616556245
E22: Mid Review(TOP300) | F22: 46028 | G22: 10632197268 | H22: 137167296625 | I22: 1526635897 | J22: 4658476535 | K22: 4402502989 | L22: =10351659+12668618+7134391+921595 -> 31076263 | M22: =11747550+17697237+8387804+199779 -> 38032370 | N22: 1322161892252
A23: SCORE BOARD | E23: Kings Land(TOP300) | F23: 46032 | G23: 10297688506 | H23: 142038184665 | I23: 1551926516 | J23: 4701099439 | K23: 4625017637 | L23: =17637283+18651486+10665494+1385522 -> 48339785 | M23: =17455273+25559800+10488314+277934 -> 53781321 | N23: 1333087725568
C24: Top DKP
C25: Top KP
C26: Top Dead
C27: Top KP Gained | E27: DKP SUMMARY | F27: X | G27: X | H27: X | I27: X | J27: X | K27: X | L27: X | M27: X | N27: X
C28: Top DKP %
B31: Date | C31: Kingdom Power | D31: Kill Points
B32: 45864 | C32: 9278618824 | D32: 61276483616
B33: 45899 | C33: 12149406514 | D33: 112058146834
B34: 45928 | C34: 12149819513 | D34: 117058934234
B35: 45949 | C35: 11507378863 | D35: 124467902534
B36: 46002 | C36: 11180721781 | D36: 129539827144
B37: 46006 | C37: 10867057311 | D37: 133580316573
B38: 46013 | C38: 10913196282 | D38: 133185732701
B39: 46028 | C39: 10632197268 | D39: 137167296625
B40: 46032 | C40: 10297688506 | D40: 142038184665
E56: Camp STATISTICS
E60: Kingdom | F60: Power | G60: Kill Points | H60: Deads | I60: T4 Kills | J60: T5 Kills | K60: T4 Deads | L60: T5 Deads | M60: RSS Assist | N60: DKP

Sheet SoC_Data
A1: Player Data | E1: Base Scan (11 December 2025) | L1: Pass 4 (11 - 15 December 2025) | S1: MGE (16 - 20 December 2025) | Z1: Altar 1 (21 - 22 December 2025) | AG1: Pass 7 (22 - 30 December 2025) | AN1: Mid Review (31/12 - 6/1 2025/2026) | AU1: Kings Land (2 - 10 January 2026)
A2: Governor ID | B2: Name | C2: Power | D2: KP | E2: T1 Kills | F2: T4 Kills | G2: T5 Kills | H2: Dead | I2: RSS Assist | J2: Scan Power | K2: Scan KP | L2: T1 Kills | M2: T4 Kills | N2: T5 Kills | O2: Dead | P2: RSS Assist | Q2: Scan Power | R2: Scan KP | S2: T1 Kills | T2: T4 Kills | U2: T5 Kills | V2: Dead | W2: RSS Assist | X2: Scan Power | Y2: Scan KP | Z2: T1 Kills | AA2: T4 Kills | AB2: T5 Kills | AC2: Dead | AD2: RSS Assist | AE2: Scan Power | AF2: Scan KP | AG2: T1 Kills | AH2: T4 Kills | AI2: T5 Kills | AJ2: Dead | AK2: RSS Assist | AL2: Scan Power | AM2: Scan KP | AN2: T1 Kills | AO2: T4 Kills | AP2: T5 Kills | AQ2: Dead | AR2: RSS Assist | AS2: Scan Power | AT2: Scan KP | AU2: T1 Kills | AV2: T4 Kills | AW2: T5 Kills | AX2: Dead | AY2: RSS Assist | AZ2: Scan Power | BA2: Scan KP
A3: 168455139 | B3: ᵁᴺOdin | C3: 110335941 | D3: 2600812023 | E3: 11402995 | F3: 57705402 | G3: 100706194 | H3: 13462892 | I3: 2095967435 | J3: 118531241 | K3: 2600812023 | L3: 11403000 | M3: 58335189 | N3: 108405411 | O3: 14144639 | P3: 2095967435 | Q3: 110170541 | R3: 2761098830 | S3: 11403000 | T3: 58335189 | U3: 108405411 | V3: 14144639 | W3: 2095967435 | X3: 112752471 | Y3: 2761098830 | Z3: 11403000 | AA3: 58341106 | AB3: 108788013 | AC3: 14144639 | AD3: 2095967435 | AE3: 111921961 | AF3: 2768810040 | AG3: 11403003 | AH3: 59165268 | AI3: 115915905 | AJ3: 14554404 | AK3: 2095967435 | AL3: 106472321 | AM3: 2919609500 | AN3: 11403003 | AO3: 59308331 | AP3: 117424645 | AQ3: 15004702 | AR3: 2095967435 | AS3: 106000621 | AT3: 2951214930 | AU3: 11403029 | AV3: 60974233 | AW3: 126272621 | AX3: 15798347 | AY3: 2095967435 | AZ3: 95168121 | BA3: 3144833587
A4: 64966340 | B4: ᵁᴺPisontije | C4: 103712620 | D4: 4150134940 | E4: 23297159 | F4: 74400483 | G4: 170087043 | H4: 18028667 | I4: 14447507139 | J4: 106017650 | K4: 4158381077 | L4: 23411497 | M4: 76167772 | N4: 180756751 | O4: 18647843 | P4: 14447507139 | Q4: 96560930 | R4: 4389523123 | S4: 23411497 | T4: 77324377 | U4: 180756751 | V4: 18647843 | W4: 14447507139 | X4: 101091016 | Y4: 4401089173 | Z4: 23411497 | AA4: 77336433 | AB4: 181120132 | AC4: 18647843 | AD4: 14447507139 | AE4: 100967826 | AF4: 4408477353 | AG4: 23411499 | AH4: 79221456 | AI4: 201018498 | AJ4: 19307446 | AK4: 14447507139 | AL4: 91866784 | AM4: 4825296079 | AN4: 23411499 | AO4: 79258230 | AP4: 202928878 | AQ4: 19307446 | AR4: 14447507139 | AS4: 94354675 | AT4: 4863871419 | AU4: 23411511 | AV4: 80260912 | AW4: 210227129 | AX4: 19380555 | AY4: 14447507139 | AZ4: 95427085 | BA4: 5019865662
A5: 145408006 | B5: Adam23 | C5: 102596686 | D5: 1200131220 | E5: 119545642 | F5: 36779995 | G5: 40342683 | H5: 12596331 | I5: 97148239 | J5: 102323387 | K5: 1208379828 | L5: 119561949 | M5: 37555260 | N5: 42373187 | O5: 12985725 | P5: 97148239 | Q5: 97570636 | R5: 1256766825 | S5: 119561949 | T5: 37563147 | U5: 42413682 | V5: 12985725 | W5: 97148239 | X5: 98707297 | Y5: 1257655595 | Z5: 119561949 | AA5: 37563147 | AB5: 42435914 | AC5: 12985725 | AD5: 97148239 | AE5: 98676637 | AF5: 1258100235 | AG5: 119612268 | AH5: 38310815 | AI5: 46176378 | AJ5: 13789687 | AK5: 97148239 | AL5: 87128577 | AM5: 1340573311 | AN5: 119614259 | AO5: 38328674 | AP5: 46435435 | AQ5: 13808661 | AR5: 97148239 | AS5: 91444187 | AT5: 1345933439 | AU5: 119626732 | AV5: 38685296 | AW5: 49104257 | AX5: 13976374 | AY5: 97148239 | AZ5: 91681627 | BA5: 1402880486
A6: 27578537 | B6: Luki92 | C6: 97578623 | D6: 2798183604 | E6: 34662036 | F6: 102342006 | G6: 89104990 | H6: 24722443 | I6: 33526939303 | J6: 86649209 | K6: 2842225317 | L6: 34697111 | M6: 102774582 | N6: 96267501 | O6: 24906584 | P6: 33526939303 | Q6: 80725359 | R6: 2989852434 | S6: 34697111 | T6: 102857101 | U6: 96267501 | V6: 24906584 | W6: 33526939303 | X6: 86396519 | Y6: 2990677624 | Z6: 34851485 | AA6: 102907147 | AB6: 96833226 | AC6: 24906584 | AD6: 33526939303 | AE6: 86598919 | AF6: 3002523459 | AG6: 34851835 | AH6: 103532739 | AI6: 102451856 | AJ6: 25562290 | AK6: 33526939303 | AL6: 81488744 | AM6: 3121152741 | AN6: 34851965 | AO6: 103697212 | AP6: 103031146 | AQ6: 25565670 | AR6: 33526939303 | AS6: 81903743 | AT6: 3134384449 | AU6: 34859699 | AV6: 104940509 | AW6: 109366473 | AX6: 26017941 | AY6: 33526939303 | AZ6: 78226207 | BA6: 3273577513
A7: 62576249 | B7: ᵁᴺUğur | C7: 95663368 | D7: 3271268940 | E7: 136762451 | F7: 101607892 | G7: 108991713 | H7: 21653131 | I7: 33189364731 | J7: 96605528 | K7: 3277365308 | L7: 136769339 | M7: 102182780 | N7: 116336781 | O7: 21994550 | P7: 33189364731 | Q7: 93677938 | R7: 3430140579 | S7: 136769339 | T7: 102182780 | U7: 116336781 | V7: 21994550 | W7: 33189364731 | X7: 94336238 | Y7: 3430140579 | Z7: 136769339 | AA7: 102182921 | AB7: 116426691 | AC7: 21994550 | AD7: 33189364731 | AE7: 93015678 | AF7: 3431940189 | AG7: 136796129 | AH7: 102985876 | AI7: 123577850 | AJ7: 22414637 | AK7: 33189364731 | AL7: 90854358 | AM7: 3582998909 | AN7: 136796129 | AO7: 103002307 | AP7: 124090835 | AQ7: 22414637 | AR7: 33189364731 | AS7: 92404468 | AT7: 3593422919 | AU7: 136842248 | AV7: 104175898 | AW7: 129228398 | AX7: 22870119 | AY7: 33949364731 | AZ7: 88269654 | BA7: 3707959639
A8: 103336195 | B8: KIM J0NGᵁᴺ | C8: 89284696 | D8: 3886208750 | E8: 54642770 | F8: 127037610 | G8: 128923463 | H8: 18459458 | I8: 33782410358 | J8: 90786056 | K8: 3886208750 | L8: 54643392 | M8: 127565565 | N8: 134012119 | O8: 18794569 | P8: 33782410358 | Q8: 86297136 | R8: 3993261810 | S8: 54643392 | T8: 127584542 | U8: 134053481 | V8: 18794569 | W8: 33782410358 | X8: 89065016 | Y8: 3994278820 | Z8: 54643392 | AA8: 127590883 | AB8: 134439824 | AC8: 18794569 | AD8: 33782410358 | AE8: 86590596 | AF8: 4002069090 | AG8: 54643392 | AH8: 127708201 | AI8: 135381181 | AJ8: 18837938 | AK8: 33782410358 | AL8: 91326082 | AM8: 4022069410 | AN8: 54643392 | AO8: 127708201 | AP8: 135381181 | AQ8: 18837938 | AR8: 33782410358 | AS8: 92212362 | AT8: 4022069410 | AU8: 54652872 | AV8: 127885478 | AW8: 137186866 | AX8: 18939597 | AY8: 33782410358 | AZ8: 91418782 | BA8: 4059957776
A9: 2463403 | B9: ᵁᴺHeliosツ | C9: 89101347 | D9: 7143949247 | E9: 30408668 | F9: 199538778 | G9: 256197391 | H9: 39990822 | I9: 10256888908 | J9: 91042347 | K9: 7158593637 | L9: 30412616 | M9: 200333134 | N9: 265876795 | O9: 40544987 | P9: 10256888908 | Q9: 83289877 | R9: 7360126105 | S9: 30412616 | T9: 202549872 | U9: 265876795 | V9: 40544987 | W9: 10256888908 | X9: 86213410 | Y9: 7382293485 | Z9: 30412616 | AA9: 202560257 | AB9: 266442213 | AC9: 40544987 | AD9: 10256888908 | AE9: 85426105 | AF9: 7393705695 | AG9: 30424005 | AH9: 203313627 | AI9: 277449525 | AJ9: 40718098 | AK9: 10256888908 | AL9: 84673431 | AM9: 7621387913 | AN9: 30424005 | AO9: 204415484 | AP9: 279873358 | AQ9: 40718098 | AR9: 10256888908 | AS9: 84911141 | AT9: 7680883143 | AU9: 30424042 | AV9: 205911206 | AW9: 297735913 | AX9: 41156294 | AY9: 10256888908 | AZ9: 81194190 | BA9: 8053097772
A10: 79650085 | B10: Keshiba ツ | C10: 89074025 | D10: 1844288620 | E10: 34537501 | F10: 58561115 | G10: 61822342 | H10: 12044507 | I10: 15131538986 | J10: 91160825 | K10: 1844288620 | L10: 34537502 | M10: 58707090 | N10: 62755078 | O10: 12110118 | P10: 15131538986 | Q10: 86691979 | R10: 1864405394 | S10: 34537502 | T10: 58707090 | U10: 62755078 | V10: 12110118 | W10: 15131538986 | X10: 90080943 | Y10: 1864405394 | Z10: 34537502 | AA10: 58707090 | AB10: 62762532 | AC10: 12110118 | AD10: 15131538986 | AE10: 91109065 | AF10: 1864554474 | AG10: 34554211 | AH10: 59509023 | AI10: 66176296 | AJ10: 13079116 | AK10: 15131538986 | AL10: 76747915 | AM10: 1940910564 | AN10: 34554211 | AO10: 59509023 | AP10: 66210526 | AQ10: 13079116 | AR10: 15131538986 | AS10: 83098015 | AT10: 1941595164 | AU10: 34594796 | AV10: 60282058 | AW10: 69781813 | AX10: 13444162 | AY10: 15131538986 | AZ10: 81083559 | BA10: 2020759923
A11: 64010776 | B11: ᵀᶜ Tequila | C11: 88294827 | D11: 2358208628 | E11: 35104753 | F11: 80510823 | G11: 75349352 | H11: 18762582 | I11: 29922279846 | J11: 85943147 | K11: 2358208628 | L11: 35104753 | M11: 80568711 | N11: 76770484 | O11: 19035238 | P11: 29922279846 | Q11: 82373857 | R11: 2387210276 | S11: 35104753 | T11: 80568711 | U11: 76770484 | V11: 19035238 | W11: 29922279846 | X11: 82619307 | Y11: 2387210276 | Z11: 35104753 | AA11: 80570388 | AB11: 76936449 | AC11: 19035238 | AD11: 29922279846 | AE11: 79317817 | AF11: 2390546346 | AG11: 35105323 | AH11: 80738775 | AI11: 78540059 | AJ11: 19373920 | AK11: 32032279846 | AL11: 78885911 | AM11: 2424302530 | AN11: 35105323 | AO11: 80753786 | AP11: 78652181 | AQ11: 19373920 | AR11: 32032279846 | AS11: 78057871 | AT11: 2426695080 | AU11: 35105324 | AV11: 81257599 | AW11: 79713168 | AX11: 19483092 | AY11: 32032279846 | AZ11: 79357941 | BA11: 2453038112
A12: 171934536 | B12: FromKiev1122 | C12: 87446620 | D12: 686911268 | E12: 22195584 | F12: 24148641 | G12: 20676569 | H12: 2221644 | I12: 958710757 | J12: 87696020 | K12: 686911268 | L12: 22195584 | M12: 24148641 | N12: 20676569 | O12: 2221644 | P12: 958710757 | Q12: 87744020 | R12: 686911268 | S12: 22195584 | T12: 24148641 | U12: 20676569 | V12: 2221644 | W12: 958710757 | X12: 87792020 | Y12: 686911268 | Z12: 22195584 | AA12: 24148641 | AB12: 20676569 | AC12: 2221644 | AD12: 958710757 | AE12: 87792020 | AF12: 686911268 | AG12: 22195584 | AH12: 24148641 | AI12: 20676569 | AJ12: 2221644 | AK12: 958710757 | AL12: 87868020 | AM12: 686911268 | AN12: 22195584 | AO12: 24148641 | AP12: 20676569 | AQ12: 2221644 | AR12: 958710757 | AS12: 87916020 | AT12: 686911268 | AU12: 22195607 | AV12: 24636205 | AW12: 22489513 | AX12: 2526075 | AY12: 958710757 | AZ12: 84923872 | BA12: 728045793
A13: 11409556 | B13: Enes 33 | C13: 87014821 | D13: 566770165 | E13: 19002385 | F13: 30738537 | G13: 12090779 | H13: 14864436 | I13: 5766935771 | J13: 88356721 | K13: 566770165 | L13: 19002385 | M13: 30738755 | N13: 12428196 | O13: 14892721 | P13: 5766935771 | Q13: 88248871 | R13: 573520685 | S13: 19002385 | T13: 30738755 | U13: 12428196 | V13: 14892721 | W13: 5766935771 | X13: 88388671 | Y13: 573520685 | Z13: 19002385 | AA13: 30738755 | AB13: 12428196 | AC13: 14892721 | AD13: 5766935771 | AE13: 88388671 | AF13: 573520685 | AG13: 19002422 | AH13: 30781500 | AI13: 12851588 | AJ13: 15648218 | AK13: 5766935771 | AL13: 73629101 | AM13: 582419822 | AN13: 19002422 | AO13: 30781500 | AP13: 12851588 | AQ13: 15648218 | AR13: 5766935771 | AS13: 73629101 | AT13: 582419822 | AU13: 19002422 | AV13: 30781500 | AW13: 12851588 | AX13: 15648218 | AY13: 5766935771 | AZ13: 73629101 | BA13: 582419822
A14: 11726598 | B14: ᵁᴺLazy Catツ | C14: 85544161 | D14: 7514837859 | E14: 84592879 | F14: 209508567 | G14: 267744853 | H14: 27941848 | I14: 30857472756 | J14: 87082220 | K14: 7532122629 | L14: 84598414 | M14: 211464435 | N14: 294751875 | O14: 28150649 | P14: 30857472756 | Q14: 84488161 | R14: 8091828324 | S14: 84598414 | T14: 211464435 | U14: 294751875 | V14: 28150649 | W14: 30857472756 | X14: 86367361 | Y14: 8091828324 | Z14: 84598414 | AA14: 211599063 | AB14: 297039940 | AC14: 28150649 | AD14: 30857472756 | AE14: 79542171 | AF14: 8138935904 | AG14: 84598614 | AH14: 214418421 | AI14: 327633233 | AJ14: 28386306 | AK14: 30857472756 | AL14: 78322442 | AM14: 8779009980 | AN14: 84598614 | AO14: 214504763 | AP14: 329333301 | AQ14: 28386306 | AR14: 30857472758 | AS14: 84048560 | AT14: 8813874760 | AU14: 84598811 | AV14: 217114325 | AW14: 360599807 | AX14: 28439075 | AY14: 31467472758 | AZ14: 81190185 | BA14: 9465326822
... A238: 109960210 | B238: LilPisontije | C238: 20175746 | D238: 3143180 | E238: 0 | F238: 62104 | G238: 126107 | H238: 253288 | I238: 858856569 | J238: 20175746 | K238: 3143180 | L238: 0 | M238: 66702 | N238: 135931 | O238: 281916 | P238: 898856569 | Q238: 19492978 | R238: 3385640 | S238: 0 | T238: 66702 | U238: 140634 | V238: 281916 | W238: 898856569 | X238: 18794082 | Y238: 3479700 | Z238: 0 | AA238: 66702 | AB238: 140634 | AC238: 281916 | AD238: 898856569 | AE238: 18801332 | AF238: 3479700 | AG238: 1228 | AH238: 93278 | AI238: 190700 | AJ238: 312394 | AK238: 898856569 | AL238: 20057756 | AM238: 4747025 | AN238: 1228 | AO238: 170917 | AP238: 264426 | AQ238: 407767 | AR238: 898856569 | AS238: 19769720 | AT238: 6997939 | AU238: 1229 | AV238: 313298 | AW238: 359153 | AX238: 537460 | AY238: 1108856569 | AZ238: 19312148 | BA238: 10316509

Sheet Performance Analysis
A1: Performance Analysis Report
A2: Final Data | G2: Player Performance | L2: Player Progress | P2: Score | S2: Player Result
A3: Governor ID | B3: Name | C3: Initial Power | D3: Final Power | E3: Initial KP | F3: Final KP | G3: Total T4 Dead *100 | H3: Total T5 Dead *200 | I3: Total Dead | J3: Total Power Diff | K3: Total KP Gained | L3: % Min KP | M3: % Min Dead | N3: % Power Loss | O3: % Goal | P3: KP Ratio Power | Q3: Dead Ratio | R3: Goal Ratio | S3: Rate
A4: 11726598 | B4: ᵁᴺLazy Catツ | C4: 85544161 | D4: 81190185 | E4: 7514837859 | F4: 9465326822 | G4: =991*100 -> 99100 | H4: =(142364+167408+186462)*200 -> 99246800 | I4: 497227 | J4: -7771235 | K4: 1933204193 | L4: 6.4150225 | M4: 0.64598695 | N4: -0.090844716 | O4: 4.2089679 | P4: 29.930077 | Q4: 5.8521103 | R4: 37.838295 | S4: Excellent
A5: 169446444 | B5: ᵁᴺLiwenツ | C5: 57611728 | D5: 56077624 | E5: 752438912 | F5: 1251807736 | G5: =(317535+154889+739)*100 -> 47316300 | H5: =(240580+247983)*200 -> 97712600 | I5: 1041820 | J5: -5433506 | K5: 497018978 | L5: 3.9175176 | M5: 2.1342639 | N5: -0.094312498 | O5: 2.4210376 | P5: 18.666982 | Q5: 16.677217 | R5: 22.189731 | S5: Excellent
A6: 169326547 | B6: ᵁᴺSexyRickツ | C6: 68321873 | D6: 63184807 | E6: 2906237594 | F6: 3507155636 | G6: =(8381+407048+45660)*100 -> 46108900 | H6: =583246*200 -> 116649200 | I6: 1329070 | J6: -7293654 | K6: 600918042 | L6: 3.3431369 | M6: 1.6803416 | N6: -0.1067543 | O6: 2.1069683 | P6: 16.076675 | Q6: 13.375575 | R6: 19.440891 | S6: Excellent
A7: 153857025 | B7: GAGS | C7: 62415625 | D7: 61416348 | E7: 657681542 | F7: 1062839116 | G7: =(298559+325605+375178)*100 -> 99934200 | H7: =(84845+74689+24307)*200 -> 36768200 | I7: 1183184 | J7: -3925465 | K7: 405157574 | L7: 2.6704062 | M7: 1.6667384 | N7: -0.062892345 | O7: 1.665017 | P7: 13.042835 | Q7: 13.276631 | R7: 15.572786 | S7: Excellent
A8: 2463403 | B8: ᵁᴺHeliosツ | C8: 89101347 | D8: 81194190 | E8: 7143949247 | F8: 8053097772 | G8: 0 | H8: =(454389+515925+195158)*200 -> 233094400 | I8: 1165472 | J8: -12771690 | K8: 872336755 | L8: 2.6165908 | M8: 1.3917972 | N8: -0.14333891 | O8: 1.7313851 | P8: 12.800141 | Q8: 11.276823 | R8: 16.153662 | S8: Excellent
A9: 172021868 | B9: ᵁᴺAnshii | C9: 68451000 | D9: 68361630 | E9: 655938793 | F9: 1119055615 | G9: =4594*100 -> 459400 | H9: =(448073+291469+53482)*200 -> 158604800 | I9: 788386 | J9: -3605490 | K9: 455819059 | L9: 2.3826193 | M9: 1.5482871 | N9: -0.052672569 | O9: 1.5081934 | P9: 11.744991 | Q9: 12.415066 | R9: 14.200213 | S9: Excellent
A10: 67071592 | B10: ᵁᴺ乄Bツ | C10: 84639977 | D10: 81967002 | E10: 9687393882 | F10: 10363196103 | G10: =(50005+807)*100 -> 5081200 | H10: =(304626+118806+353116+9858)*200 -> 157281200 | I10: 837218 | J10: -5727042 | K10: 648565277 | L10: 2.2822762 | M10: 1.1100242 | N10: -0.067663558 | O10: 1.4901351 | P10: 11.29247 | Q10: 9.227324 | R10: 14.042161 | S10: Excellent
A11: 146428825 | B11: Ray i | C11: 67591513 | D11: 61074272 | E11: 1595034768 | F11: 1989393617 | G11: 0 | H11: =(225876+875895)*200 -> 220354200 | I11: 1074942 | J11: -10062251 | K11: 377738433 | L11: 2.1334752 | M11: 2.3080424 | N11: -0.14886856 | O11: 1.3432128 | P11: 10.621417 | Q11: 17.941209 | R11: 12.756248 | S11: Excellent
A12: 74556991 | B12: 乄Narcissus | C12: 81990559 | D12: 70819870 | E12: 2297498275 | F12: 2836706401 | G12: =(12804+47104+23429)*100 -> 8333700 | H12: =(398680+521519+374643)*200 -> 258968400 | I12: 1378210 | J12: -14216299 | K12: 539208126 | L12: 1.9956809 | M12: 1.9086991 | N12: -0.17338946 | O12: 1.2976023 | P12: 10 | Q12: 15.036552 | R12: 12.357049 | S12: Excellent
A13: 171355737 | B13: ᵁᴺUğur Jr | ShүNøX ゎ | C13: 68675561 | D13: 61351576 | E13: 355644809 | F13: 731073190 | G13: =(4964+58058+6513)*100 -> 6953500 | H13: =(559543+528711+424100)*200 -> 302470800 | I13: 1569007 | J13: -13922823 | K13: 375428381 | L13: 1.9434176 | M13: 2.9846013 | N13: -0.2027333 | O13: 1.2310395 | P13: 9.7643062 | Q13: 22.862216 | R13: 11.77447 | S13: Excellent
A14: 64966340 | B14: ᵁᴺPisontije | C14: 103712620 | D14: 95427085 | E14: 4150134940 | F14: 5019865662 | G14: 0 | H14: =(445238+525289+381360)*200 -> 270377400 | I14: 1351888 | J14: -15120651 | K14: 849918535 | L14: 1.8071736 | M14: 1.2162547 | N14: -0.14579374 | O14: 1.2309612 | P14: 9.1498814 | Q14: 10 | R14: 11.773784 | S14: Excellent
A15: 171503078 | B15: メCalメ | C15: 75621607 | D15: 70774961 | E15: 1074240672 | F15: 1481376399 | G15: =(267470+264758)*100 -> 53222800 | H15: =(98957+193316+81039)*200 -> 74662400 | I15: 905541 | J15: -9936221 | K15: 407135727 | L15: 1.8014916 | M15: 1.0686621 | N15: -0.13139394 | O15: 1.1546846 | P15: 9.1242571 | Q15: 8.9264735 | R15: 11.106186 | S15: Excellent
A16: 98107237 | B16: 亗 Intersect | C16: 82512792 | D16: 69457009 | E16: 2374805436 | F16: 2827549678 | G16: 0 | H16: =(649579+281327+391560)*200 -> 264493200 | I16: 1326419 | J16: -15194833 | K16: 439585462 | L16: 1.5774817 | M16: 1.8389597 | N16: -0.18415124 | O16: 1.0282971 | P16: 8.1140306 | Q16: 14.529297 | R16: 10 | S16: Excellent
A17: 27578537 | B17: Luki92 | C17: 97578623 | D17: 78226207 | E17: 2798183604 | F17: 3273577513 | G17: =(4450+17994+4318)*100 -> 2676200 | H17: =(254079+877349+122080+45)*200 -> 250710600 | I17: 1295498 | J17: -14094162 | K17: 430527006 | L17: 1.4449185 | M17: 1.6635904 | N17: -0.14443903 | O17: 0.94713116 | P17: 7.5162054 | Q17: 13.253734 | R17: 9.2896088 | S17: Excellent
A18: 171604682 | B18: ᵁᴺDaddyツ | ᵁᴺPraMaツ | C18: 72394989 | D18: 64841606 | E18: 1058823381 | F18: 1356696374 | G18: =233*100 -> 23300 | H18: =(368776+356347+176352)*200 -> 180295000 | I18: 901708 | J18: -8514476 | K18: 276047386 | L18: 1.3838431 | M18: 1.6881941 | N18: -0.1176114 | O18: 0.87863215 | P18: 7.2407712 | Q18: 13.432691 | R18: 8.6900825 | S18: Excellent
A19: 141154852 | B19: 亗Zolotashkoツ | C19: 75835286 | D19: 67250544 | E19: 2406316835 | F19: 2725799737 | G19: =(145076+374041+128203)*100 -> 64732000 | H19: =(197777+646727+375612)*200 -> 244023200 | I19: 1582869 | J19: -10968599 | K19: 294000670 | L19: 1.2854181 | M19: 2.5525791 | N19: -0.14463714 | O19: 0.82467247 | P19: 6.7969003 | Q19: 19.719867 | R19: 8.2178094 | S19: Excellent
A20: 55242490 | B20: R7R7 | C20: 67356763 | D20: 68536876 | E20: 792695620 | F20: 1020831674 | G20: =(293674+11780+183290)*100 -> 48874400 | H20: =(5467+251835+1494)*200 -> 51759200 | I20: 747540 | J20: -3723150 | K20: 228136054 | L20: 1.2798858 | M20: 1.0473016 | N20: -0.055275073 | O20: 0.8061699 | P20: 6.7719509 | Q20: 8.7711055 | R20: 8.0558687 | S20: Excellent
A21: 62576249 | B21: ᵁᴺUğur | C21: 95663368 | D21: 88269654 | E21: 3271268940 | F21: 3707959639 | G21: 0 | H21: =(670578+451182+95228)*200 -> 243397600 | I21: 1216988 | J21: -8994174 | K21: 430594331 | L21: 1.129179 | M21: 1.2996545 | N21: -0.094018998 | O21: 0.75569534 | P21: 6.0923024 | Q21: 10.606616 | R21: 7.6140984 | S21: Excellent
A22: 143612450 | B22: NT ĐVL1 | C22: 42845006 | D22: 41172361 | E22: 485592936 | F22: 553982957 | G22: =(165324+236062+11503)*100 -> 41288900 | H22: 0 | I22: 421756 | J22: -3739808 | K22: 68390021 | L22: 1.0552851 | M22: 1.5867848 | N22: -0.087286906 | O22: 0.66156318 | P22: 5.7590603 | Q22: 12.695082 | R22: 6.7902224 | S22: Good
A23: 171697263 | B23: ᵁᴺFiLLer97 | C23: 41671559 | D23: 55468774 | E23: 354685334 | F23: 419441559 | G23: =(388009+830514+253235)*100 -> 147175800 | H23: =(369+422367)*200 -> 84547200 | I23: 1894494 | J23: 9135678 | K23: 64756225 | L23: 0.9141997 | M23: 7.5214489 | N23: 0.21923053 | O23: 0.56804182 | P23: 5.122802 | Q23: 55.861354 | R23: 5.9716921 | S23: Good
A24: 169672885 | B24: H ム I D E R | C24: 53730941 | D24: 48998691 | E24: 335424198 | F24: 428904904 | G24: =(411015+162877+373018+920)*100 -> 94783000 | H24: =(2257+201008)*200 -> 40653000 | I24: 1211453 | J24: -6217242 | K24: 93103726 | L24: 0.91081634 | M24: 2.5640569 | N24: -0.11571065 | O24: 0.55966091 | P24: 5.107544 | Q24: 19.803351 | R24: 5.8983396 | S24: Good
A25: 48741756 | B25: ᵁᴺ・ Maka | C25: 81883299 | D25: 73738028 | E25: 2851420244 | F25: 3122497864 | G25: =4389*100 -> 438900 | H25: =(359671+844563+89514)*200 -> 258749600 | I25: 1298138 | J25: -11547705 | K25: 248582558 | L25: 0.90569401 | M25: 1.8258011 | N25: -0.14102638 | O25: 0.58964783 | P25: 5.0844436 | Q25: 14.433586 | R25: 6.1607951 | S25: Good
A26: 168455139 | B26: ᵁᴺOdin | C26: 110335941 | D26: 95168121 | E26: 2600812023 | F26: 3144833587 | G26: =5132*100 -> 513200 | H26: =(522814+1418209+389300)*200 -> 466064600 | I26: 2335455 | J26: -25945050 | K26: 544021564 | L26: 0.90089755 | M26: 1.716404 | N26: -0.23514595 | O26: 0.62640172 | P26: 5.0628128 | Q26: 13.637878 | R26: 6.4824774 | S26: Good
A27: 181734011 | B27: CABJLorena | C27: 30917143 | D27: 29343046 | E27: 52815309 | F27: 84623892 | G27: =(287371+622904+24776)*100 -> 93505100 | H27: 0 | I27: 935052 | J27: -2409586 | K27: 31808583 | L27: 0.8900115 | M27: 3 | N27: -0.077936891 | O27: 0.68957423 | P27: 5.0137196 | Q27: 22.97422 | R27: 7.0353844 | S27: Good
A28: 172029365 | B28: ᵁᴺCTAMツ | C28: 40744969 | D28: 37413149 | E28: 122016779 | F28: 171300154 | G28: =(211682+463137+99704)*100 -> 77452300 | H28: 0 | I28: 1409264 | J28: -4158699 | K28: 49283375 | L28: 0.8437067 | M28: 3.75 | N28: -0.10206656 | O28: 0.53685727 | P28: 4.804897 | Q28: 1.6501252 | R28: 5.6987544 | S28: Good
A29: 120029911 | B29: Ħeřr Şimôñ | C29: 70843152 | D29: 64051644 | E29: 838856406 | F29: 1005139677 | G29: =2618*100 -> 261800 | H29: =(326056+492691+88034+21701)*200 -> 185696400 | I29: 931073 | J29: -12047486 | K29: 164912232 | L29: 0.81658179 | M29: 1.7212767 | N29: -0.17005858 | O29: 0.51893729 | P29: 4.6825708 | Q29: 13.67332 | R29: 5.5419128 | S29: Good
A30: 171491377 | B30: ᵀᵒᴿQuyet | C30: 70777139 | D30: 70418750 | E30: 362277925 | F30: 522106936 | G30: =(80390+380585+124632)*100 -> 58560700 | H30: =(39531+53795+84280)*200 -> 35521200 | I30: 763236 | J30: -2468189 | K30: 159829011 | L30: 0.80456238 | M30: 0.8842105 | N30: -0.034872687 | O30: 0.51067875 | P30: 4.6283664 | Q30: 7.5848491 | R30: 5.4696313 | S30: Good
A31: 176044158 | B31: メSuper Manメ | C31: 45412641 | D31: 42667600 | E31: 71273563 | F31: 131159590 | G31: =(682721+796767+393239)*100 -> 187272700 | H31: 0 | I31: 1872727 | J31: -4898298 | K31: 59886027 | L31: 0.77862774 | M31: 5.2885565 | N31: -0.10786199 | O31: 0.48107611 | P31: 4.5114079 | Q31: 39.620226 | R31: 5.2105391 | S31: Good
A32: 171609840 | B32: KaizerX | C32: 64520826 | D32: 61633448 | E32: 466804153 | F32: 587705450 | G32: =(105160+18569)*100 -> 12372900 | H32: =(141153+185740+59395)*200 -> 77257600 | I32: 510018 | J32: -6493909 | K32: 120901297 | L32: 0.76020913 | M32: 1.0424108 | N32: -0.10064826 | O32: 0.47531995 | P32: 4.4283448 | Q32: 8.7355323 | R32: 5.1601593 | S32: Good
A33: 172033754 | B33: Dreckschlumpf | C33: 69859129 | D33: 65852776 | E33: 310231381 | F33: 484872769 | G33: =(42145+170778+222458)*100 -> 43538100 | H33: =(139012+695322+5805)*200 -> 168027800 | I33: 1280063 | J33: -7214514 | K33: 136229282 | L33: 0.70965517 | M33: 2.0527463 | N33: -0.10327232 | O33: 0.44932053 | P33: 4.2003596 | Q33: 16.084291 | R33: 4.9326036 | S33: Good
A34: 170728362 | B34: 乂 マoddi 乂 | C34: 64505395 | D34: 55156572 | E34: 399939799 | F34: 523973532 | G34: =(68191+110356+185158)*100 -> 36370500 | H34: =(197300+529032+238187)*200 -> 192903800 | I34: 1328224 | J34: -11836533 | K34: 111755091 | L34: 0.69890013 | M34: 2.6521666 | N34: -0.18349679 | O34: 0.43713145 | P34: 4.1518572 | Q34: 20.444225 | R34: 4.8259207 | S34: Good
A35: 170866748 | B35: Tzilacatzin | C35: 74655691 | D35: 68876564 | E35: 494086077 | F35: 640450638 | G35: =(262228+256152+221290+43461)*100 -> 78313100 | H35: =15241*200 -> 3048200 | I35: 798373 | J35: -9394127 | K35: 143944841 | L35: 0.64599699 | M35: 0.68858179 | N35: -0.1258327 | O35: 0.41360357 | P35: 3.9132778 | Q35: 6.1619274 | R35: 4.6199968 | S35: Good
A36: 155534128 | B36: ŻŸŁÜĶ㋡ | C36: 66945449 | D36: 61615659 | E36: 1000110292 | F36: 1106830933 | G36: =(88517+119295+123607+10929)*100 -> 34234800 | H36: =(213875+163319+187053+27382)*200 -> 118325800 | I36: 933977 | J36: -6683348 | K36: 106720641 | L36: 0.62299689 | M36: 1.6495963 | N36: -0.099832746 | O36: 0.39136838 | P36: 3.8095534 | Q36: 13.151947 | R36: 4.425387 | S36: Good
A37: 172041454 | B37: ᵁᴺSeckin34 | C37: 72409940 | D37: 64561350 | E37: 379804337 | F37: 518612647 | G37: 0 | H37: =(651855+718042+210848)*200 -> 316149000 | I37: 1580745 | J37: -16223814 | K37: 132905021 | L37: 0.62188495 | M37: 2.7786176 | N37: -0.22405507 | O37: 0.39689041 | P37: 3.8045388 | Q37: 21.363977 | R37: 4.4737177 | S37: Good
A38: 169427770 | B38: ᵁᴺ Saxon | C38: 77346694 | D38: 70123784 | E38: 653935051 | F38: 811052722 | G38: =(37232+23478+5077)*100 -> 6578700 | H38: =(428201+760947+311770)*200 -> 300183600 | I38: 1567045 | J38: -11623156 | K38: 154190307 | L38: 0.60814902 | M38: 2.3151383 | N38: -0.15027347 | O38: 0.39337835 | P38: 3.7425933 | Q38: 17.992821 | R38: 4.4429789 | S38: Good
A39: 156479771 | B39: ᵁᴺSnowWoLF | C39: 74985735 | D39: 74146500 | E39: 1549222299 | F39: 1686171829 | G39: =(229719+6234)*100 -> 23595300 | H39: =(76814+56300+7987)*200 -> 28220200 | I39: 377054 | J39: -5295874 | K39: 136257441 | L39: 0.60536187 | M39: 0.4345711 | N39: -0.070625086 | O39: 0.38789034 | P39: 3.730024 | Q39: 4.3143595 | R39: 4.3949461 | S39: Good
A40: 145033056 | B40: Тiамат 义 | C40: 51702333 | D40: 49233153 | E40: 430246223 | F40: 490830169 | G40: =(602274+532740+217530)*100 -> 135254400 | H40: =51077*200 -> 10215400 | I40: 1403621 | J40: -5206994 | K40: 59220259 | L40: 0.58276644 | M40: 2.77 | N40: -0.10071101 | O40: 0.35806618 | P40: 3.6281246 | Q40: 21 | R40: 4.133915 | S40: Good
...

Sheet Kings Land Report
A1: Kings Land Report (2 - 10 January 2026)
A2: Basic Data | I2: Requirements | K2: Player Goal | L2: Results | U2: Player Progress | X2: Rank
A3: Governor ID | B3: Name | C3: Power | D3: KP | E3: KL KP Gained | F3: KL T4 Kills | G3: KL T5 Kills | H3: KL Dead | I3: Minimum KP | J3: Minimum Dead | K3: KP Goal | L3: T1 Trade? | M3: Total T4 Kills | N3: Total T5 Kills | O3: Total Kills | P3: Total T4 Dead *100 | Q3: Total T5 Dead *200 | R3: Total Dead | S3: Total Power Diff | T3: Total KP Gained | U3: % Min KP | V3: % Min Dead | W3: % Goal | X3: Goal | Y3: KP Gained
A4: 11726598 | B4: ᵁᴺLazy Catツ | C4: 81190185 | D4: 9465326822 | E4: 651452062 | F4: 2609562 | G4: 31266506 | H4: 52769 | I4: 3.013558e+08 | J4: 1.5378933e+08 | K4: 4.59306e+08 | L4: 11467 | M4: 7605758 | N4: 92854954 | O4: 100460712 | P4: =991*100 -> 99100 | Q4: =(142364+167408+186462)*200 -> 99246800 | R4: 497227 | S4: -7771235 | T4: 1933204193 | U4: 6.4150225 | V4: 0.65 | W4: 4.2089679 | X4: =RANK(W4,($W$4:$W$181),0)+COUNTIF($W$4:W4,W4)-1 -> 1 | Y4: =RANK(T4,($T$4:$T$181),0)+COUNTIF($T$4:T4,T4)-1 -> 1
A5: 169446444 | B5: ᵁᴺLiwenツ | C5: 56077624 | D5: 1251807736 | E5: 114506121 | F5: 475504 | G5: 5487549 | H5: 112183 | I5: 1.268709e+08 | J5: 67952655 | K5: 2.0529172e+08 | L5: 12811 | M5: 1857586 | N5: 23920409 | O5: 25777995 | P5: =(317535+154889+739)*100 -> 47316300 | Q5: =(240580+247983)*200 -> 97712600 | R5: 1041820 | S5: -5433506 | T5: 497018978 | U5: 3.9175176 | V5: 2.13 | W5: 2.4210376 | X5: =RANK(W5,($W$4:$W$181),0)+COUNTIF($W$4:W5,W5)-1 -> 2 | Y5: =RANK(T5,($T$4:$T$181),0)+COUNTIF($T$4:T5,T5)-1 -> 8
A6: 169326547 | B6: ᵁᴺSexyRickツ | C6: 63184807 | D6: 3507155636 | E6: 156027813 | F6: 655064 | G6: 7473724 | H6: 322665 | I6: 1.7974677e+08 | J6: 96860127 | K6: 2.8520507e+08 | L6: 242130 | M6: 2878224 | N6: 28598850 | O6: 31477074 | P6: =(8381+407048+45660)*100 -> 46108900 | Q6: =583246*200 -> 116649200 | R6: 1329070 | S6: -7293654 | T6: 600918042 | U6: 3.3431369 | V6: 1.68 | W6: 2.1069683 | X6: =RANK(W6,($W$4:$W$181),0)+COUNTIF($W$4:W6,W6)-1 -> 3 | Y6: =RANK(T6,($T$4:$T$181),0)+COUNTIF($T$4:T6,T6)-1 -> 5
A7: 2463403 | B7: ᵁᴺHeliosツ | C7: 81194190 | D7: 8053097772 | E7: 372214629 | F7: 1495722 | G7: 17862555 | H7: 438196 | I7: 3.3338677e+08 | J7: 1.6747728e+08 | K7: 5.038375e+08 | L7: 15374 | M7: 4155690 | N7: 41538522 | O7: 45694212 | P7: 0 | Q7: =(454389+515925+195158)*200 -> 233094400 | R7: 1165472 | S7: -12771690 | T7: 872336755 | U7: 2.6165908 | V7: 1.39 | W7: 1.7313851 | X7: =RANK(W7,($W$4:$W$181),0)+COUNTIF($W$4:W7,W7)-1 -> 4 | Y7: =RANK(T7,($T$4:$T$181),0)+COUNTIF($T$4:T7,T7)-1 -> 2
A8: 153857025 | B8: GAGS | C8: 61416348 | D8: 1062839116 | E8: 184182576 | F8: 1683679 | G8: 8366403 | H8: 524987 | I8: 1.5172133e+08 | J8: 82017909 | K8: 2.433354e+08 | L8: 62893 | M8: 2778876 | N8: 18866668 | O8: 21645544 | P8: =(298559+325605+375178)*100 -> 99934200 | Q8: =(84845+74689+24307)*200 -> 36768200 | R8: 1183184 | S8: -3925465 | T8: 405157574 | U8: 2.6704062 | V8: 1.67 | W8: 1.665017 | X8: =RANK(W8,($W$4:$W$181),0)+COUNTIF($W$4:W8,W8)-1 -> 5 | Y8: =RANK(T8,($T$4:$T$181),0)+COUNTIF($T$4:T8,T8)-1 -> 14
A9: 172021868 | B9: ᵁᴺAnshii | C9: 68361630 | D9: 1119055615 | E9: 136533340 | F9: 610991 | G9: 6521170 | H9: 261125 | I9: 1.9131007e+08 | J9: 1.027356e+08 | K9: 3.0222852e+08 | L9: 6276 | M9: 1597117 | N9: 21992177 | O9: 23589294 | P9: =4594*100 -> 459400 | Q9: =(448073+291469+53482)*200 -> 158604800 | R9: 788386 | S9: -3605490 | T9: 455819059 | U9: 2.3826193 | V9: 1.55 | W9: 1.5081934 | X9: =RANK(W9,($W$4:$W$181),0)+COUNTIF($W$4:W9,W9)-1 -> 6 | Y9: =RANK(T9,($T$4:$T$181),0)+COUNTIF($T$4:T9,T9)-1 -> 9
A10: 67071592 | B10: ᵁᴺ乄Bツ | C10: 81967002 | D10: 10363196103 | E10: 221753397 | F10: 1509116 | G10: 10317842 | H10: 237106 | I10: 2.8417475e+08 | J10: 1.4626924e+08 | K10: 4.3523924e+08 | L10: 225404 | M10: 3568069 | N10: 30628513 | O10: 34196582 | P10: =(50005+807)*100 -> 5081200 | Q10: =(304626+118806+353116+9858)*200 -> 157281200 | R10: 837218 | S10: -5727042 | T10: 648565277 | U10: 2.2822762 | V10: 1.11 | W10: 1.4901351 | X10: =RANK(W10,($W$4:$W$181),0)+COUNTIF($W$4:W10,W10)-1 -> 7 | Y10: =RANK(T10,($T$4:$T$181),0)+COUNTIF($T$4:T10,T10)-1 -> 4
A11: 146428825 | B11: Ray i | C11: 61074272 | D11: 1989393617 | E11: 106168932 | F11: 5684284 | G11: 2442829 | H11: 403983 | I11: 1.7705311e+08 | J11: 95472338 | K11: 2.8122011e+08 | L11: 2692153 | M11: 12110224 | N11: 12717522 | O11: 24827746 | P11: 0 | Q11: =(225876+875895)*200 -> 220354200 | R11: 1074942 | S11: -10062251 | T11: 377738433 | U11: 2.1334752 | V11: 2.31 | W11: 1.3432128 | X11: =RANK(W11,($W$4:$W$181),0)+COUNTIF($W$4:W11,W11)-1 -> 8 | Y11: =RANK(T11,($T$4:$T$181),0)+COUNTIF($T$4:T11,T11)-1 -> 15
A12: 74556991 | B12: 乄Narcissus | C12: 70819870 | D12: 2836706401 | E12: 152631917 | F12: 685620 | G12: 7288603 | H12: 72875 | I12: 2.7018755e+08 | J12: 1.4004413e+08 | K12: 4.1554191e+08 | L12: 52658 | M12: 2715095 | N12: 25600717 | O12: 28315812 | P12: =(12804+47104+23429)*100 -> 8333700 | Q12: =(398680+521519+374643)*200 -> 258968400 | R12: 1378210 | S12: -14216299 | T12: 539208126 | U12: 1.9956809 | V12: 1.91 | W12: 1.2976023 | X12: =RANK(W12,($W$4:$W$181),0)+COUNTIF($W$4:W12,W12)-1 -> 9 | Y12: =RANK(T12,($T$4:$T$181),0)+COUNTIF($T$4:T12,T12)-1 -> 7
A13: 171355737 | B13: ᵁᴺUğur Jr | ShүNøX ゎ | C13: 61351576 | D13: 731073190 | E13: 74863470 | F13: 405353 | G13: 3540497 | H13: 13106 | I13: 1.9317947e+08 | J13: 1.0367358e+08 | K13: 3.0496859e+08 | L13: 1102536 | M13: 11343937 | N13: 12935530 | O13: 24279467 | P13: =(4964+58058+6513)*100 -> 6953500 | Q13: =(559543+528711+424100)*200 -> 302470800 | R13: 1569007 | S13: -13922823 | T13: 375428381 | U13: 1.9434176 | V13: 2.98 | W13: 1.2310395 | X13: =RANK(W13,($W$4:$W$181),0)+COUNTIF($W$4:W13,W13)-1 -> 10 | Y13: =RANK(T13,($T$4:$T$181),0)+COUNTIF($T$4:T13,T13)-1 -> 16
A14: 64966340 | B14: ᵁᴺPisontije | C14: 95427085 | D14: 5019865662 | E14: 155994243 | F14: 1002682 | G14: 7298251 | H14: 73109 | I14: 4.7030265e+08 | J14: 2.2230328e+08 | K14: 6.9045112e+08 | L14: 114352 | M14: 4703824 | N14: 40140086 | O14: 44843910 | P14: 0 | Q14: =(445238+525289+381360)*200 -> 270377400 | R14: 1351888 | S14: -15120651 | T14: 849918535 | U14: 1.8071736 | V14: 1.22 | W14: 1.2309612 | X14: =RANK(W14,($W$4:$W$181),0)+COUNTIF($W$4:W14,W14)-1 -> 11 | Y14: =RANK(T14,($T$4:$T$181),0)+COUNTIF($T$4:T14,T14)-1 -> 3
A15: 171503078 | B15: メCalメ | C15: 70774961 | D15: 1481376399 | E15: 122896415 | F15: 1443697 | G15: 5422712 | H15: 227441 | I15: 2.2599923e+08 | J15: 1.196685e+08 | K15: 3.5259476e+08 | L15: 30552 | M15: 2280219 | N15: 19216018 | O15: 21496237 | P15: =(267470+264758)*100 -> 53222800 | Q15: =(98957+193316+81039)*200 -> 74662400 | R15: 905541 | S15: -9936221 | T15: 407135727 | U15: 1.8014916 | V15: 1.07 | W15: 1.1546846 | X15: =RANK(W15,($W$4:$W$181),0)+COUNTIF($W$4:W15,W15)-1 -> 12 | Y15: =RANK(T15,($T$4:$T$181),0)+COUNTIF($T$4:T15,T15)-1 -> 13
A16: 98107237 | B16: 亗 Intersect | C16: 69457009 | D16: 2827549678 | E16: 234182386 | F16: 1322265 | G16: 11047986 | H16: 688146 | I16: 2.786628e+08 | J16: 1.4382762e+08 | K16: 4.2748878e+08 | L16: 28240 | M16: 2253679 | N16: 20852140 | O16: 23105819 | P16: 0 | Q16: =(649579+281327+391560)*200 -> 264493200 | R16: 1326419 | S16: -15194833 | T16: 439585462 | U16: 1.5774817 | V16: 1.84 | W16: 1.0282971 | X16: =RANK(W16,($W$4:$W$181),0)+COUNTIF($W$4:W16,W16)-1 -> 13 | Y16: =RANK(T16,($T$4:$T$181),0)+COUNTIF($T$4:T16,T16)-1 -> 10
A17: 27578537 | B17: Luki92 | C17: 78226207 | D17: 3273577513 | E17: 139193064 | F17: 1243297 | G17: 6335327 | H17: 452271 | I17: 2.9795937e+08 | J17: 1.5231321e+08 | K17: 4.5455901e+08 | L17: 197533 | M17: 2515984 | N17: 20261483 | O17: 22777467 | P17: =(4450+17994+4318)*100 -> 2676200 | Q17: =(254079+877349+122080+45)*200 -> 250710600 | R17: 1295498 | S17: -14094162 | T17: 430527006 | U17: 1.4449185 | V17: 1.66 | W17: 0.94713116 | X17: =RANK(W17,($W$4:$W$181),0)+COUNTIF($W$4:W17,W17)-1 -> 14 | Y17: =RANK(T17,($T$4:$T$181),0)+COUNTIF($T$4:T17,T17)-1 -> 12
A18: 171604682 | B18: ᵁᴺDaddyツ | ᵁᴺPraMaツ | C18: 64841606 | D18: 1356696374 | E18: 65611255 | F18: 787468 | G18: 2885915 | H18: 171865 | I18: 1.9947882e+08 | J18: 1.0681135e+08 | K18: 3.1417856e+08 | L18: 268731 | M18: 4272984 | N18: 11661122 | O18: 15934106 | P18: =233*100 -> 23300 | Q18: =(368776+356347+176352)*200 -> 180295000 | R18: 901708 | S18: -8514476 | T18: 276047386 | U18: 1.3838431 | V18: 1.69 | W18: 0.87863215 | X18: =RANK(W18,($W$4:$W$181),0)+COUNTIF($W$4:W18,W18)-1 -> 15 | Y18: =RANK(T18,($T$4:$T$181),0)+COUNTIF($T$4:T18,T18)-1 -> 18
A19: 141154852 | B19: 亗Zolotashkoツ | C19: 67250544 | D19: 2725799737 | E19: 47185956 | F19: 1271840 | G19: 1715696 | H19: 79304 | I19: 2.2871987e+08 | J19: 1.2095813e+08 | K19: 3.5650598e+08 | L19: 1269151 | M19: 9290256 | N19: 9842819 | O19: 19133075 | P19: =(145076+374041+128203)*100 -> 64732000 | Q19: =(197777+646727+375612)*200 -> 244023200 | R19: 1582869 | S19: -10968599 | T19: 294000670 | U19: 1.2854181 | V19: 2.55 | W19: 0.82467247 | X19: =RANK(W19,($W$4:$W$181),0)+COUNTIF($W$4:W19,W19)-1 -> 16 | Y19: =RANK(T19,($T$4:$T$181),0)+COUNTIF($T$4:T19,T19)-1 -> 17
A20: 55242490 | B20: R7R7 | C20: 68536876 | D20: 1020831674 | E20: 54310711 | F20: 659803 | G20: 2385395 | H20: 131029 | I20: 1.782472e+08 | J20: 96088466 | K20: 2.8298756e+08 | L20: 924169 | M20: 3562401 | N20: 9615766 | O20: 13178167 | P20: =(293674+11780+183290)*100 -> 48874400 | Q20: =(5467+251835+1494)*200 -> 51759200 | R20: 747540 | S20: -3723150 | T20: 228136054 | U20: 1.2798858 | V20: 1.05 | W20: 0.8061699 | X20: =RANK(W20,($W$4:$W$181),0)+COUNTIF($W$4:W20,W20)-1 -> 17 | Y20: =RANK(T20,($T$4:$T$181),0)+COUNTIF($T$4:T20,T20)-1 -> 20
A21: 62576249 | B21: ᵁᴺUğur | C21: 88269654 | D21: 3707959639 | E21: 114536720 | F21: 1173591 | G21: 5137563 | H21: 455482 | I21: 3.81334e+08 | J21: 1.8727869e+08 | K21: 5.6979885e+08 | L21: 79797 | M21: 2568006 | N21: 20236685 | O21: 22804691 | P21: 0 | Q21: =(670578+451182+95228)*200 -> 243397600 | R21: 1216988 | S21: -8994174 | T21: 430594331 | U21: 1.129179 | V21: 1.3 | W21: 0.75569534 | X21: =RANK(W21,($W$4:$W$181),0)+COUNTIF($W$4:W21,W21)-1 -> 18 | Y21: =RANK(T21,($T$4:$T$181),0)+COUNTIF($T$4:T21,T21)-1 -> 11
A22: 181734011 | B22: CABJLorena | C22: 29343046 | D22: 84623892 | E22: 21361639 | F22: 751904 | G22: 690098 | H22: 652278 | I22: 35739519 | J22: -3000831.1 | K22: 46127859 | L22: 15746 | M22: 1052604 | N22: 1061579 | O22: 2114183 | P22: =(287371+622904+24776)*100 -> 93505100 | Q22: 0 | R22: 935052 | S22: -2409586 | T22: 31808583 | U22: 0.8900115 | V22: 3 | W22: 0.68957423 | X22: =RANK(W22,($W$4:$W$181),0)+COUNTIF($W$4:W22,W22)-1 -> 19 | Y22: =RANK(T22,($T$4:$T$181),0)+COUNTIF($T$4:T22,T22)-1 -> 77
A23: 143612450 | B23: NT ĐVL1 | C23: 41172361 | D23: 553982957 | E23: 46796141 | F23: 381642 | G23: 2148977 | H23: 263919 | I23: 64807152 | J23: 26020479 | K23: 1.033764e+08 | L23: 21 | M23: 458922 | N23: 3190031 | O23: 3648953 | P23: =(165324+236062+11503)*100 -> 41288900 | Q23: 0 | R23: 421756 | S23: -3739808 | T23: 68390021 | U23: 1.0552851 | V23: 1.59 | W23: 0.66156318 | X23: =RANK(W23,($W$4:$W$181),0)+COUNTIF($W$4:W23,W23)-1 -> 20 | Y23: =RANK(T23,($T$4:$T$181),0)+COUNTIF($T$4:T23,T23)-1 -> 52
A24: 168455139 | B24: ᵁᴺOdin | C24: 95168121 | D24: 3144833587 | E24: 193618657 | F24: 1665902 | G24: 8847976 | H24: 793645 | I24: 6.0386618e+08 | J24: 2.7183449e+08 | K24: 8.684867e+08 | L24: 34 | M24: 3268831 | N24: 25566427 | O24: 28835258 | P24: =5132*100 -> 513200 | Q24: =(522814+1418209+389300)*200 -> 466064600 | R24: 2335455 | S24: -25945050 | T24: 544021564 | U24: 0.90089755 | V24: 1.72 | W24: 0.62640172 | X24: =RANK(W24,($W$4:$W$181),0)+COUNTIF($W$4:W24,W24)-1 -> 21 | Y24: =RANK(T24,($T$4:$T$181),0)+COUNTIF($T$4:T24,T24)-1 -> 6
A25: 48741756 | B25: ᵁᴺ・ Maka | C25: 73738028 | D25: 3122497864 | E25: 100849746 | F25: 1046816 | G25: 4519031 | H25: 543917 | I25: 2.7446638e+08 | J25: 1.4195878e+08 | K25: 4.2157801e+08 | L25: 110799 | M25: 2226232 | N25: 11314663 | O25: 13540895 | P25: =4389*100 -> 438900 | Q25: =(359671+844563+89514)*200 -> 258749600 | R25: 1298138 | S25: -11547705 | T25: 248582558 | U25: 0.90569401 | V25: 1.83 | W25: 0.58964783 | X25: =RANK(W25,($W$4:$W$181),0)+COUNTIF($W$4:W25,W25)-1 -> 22 | Y25: =RANK(T25,($T$4:$T$181),0)+COUNTIF($T$4:T25,T25)-1 -> 19
A26: 171697263 | B26: ᵁᴺFiLLer97 | C26: 55468774 | D26: 419441559 | E26: 19192589 | F26: 480219 | G26: 719414 | H26: 582376 | I26: 70833785 | J26: 30808293 | K26: 1.1399904e+08 | L26: 16947 | M26: 1070585 | N26: 2701106 | O26: 3771691 | P26: =(388009+830514+253235)*100 -> 147175800 | Q26: =(369+422367)*200 -> 84547200 | R26: 1894494 | S26: 9135678 | T26: 64756225 | U26: 0.9141997 | V26: 7.52 | W26: 0.56804182 | X26: =RANK(W26,($W$4:$W$181),0)+COUNTIF($W$4:W26,W26)-1 -> 23 | Y26: =RANK(T26,($T$4:$T$181),0)+COUNTIF($T$4:T26,T26)-1 -> 53
A27: 169672885 | B27: H ム I D E R | C27: 48998691 | D27: 428904904 | E27: 27726597 | F27: 289420 | G27: 1241585 | H27: 471761 | I27: 1.0222009e+08 | J27: 52820982 | K27: 1.6635739e+08 | L27: 46961 | M27: 891218 | N27: 4209003 | O27: 5100221 | P27: =(411015+162877+373018+920)*100 -> 94783000 | Q27: =(2257+201008)*200 -> 40653000 | R27: 1211453 | S27: -6217242 | T27: 93103726 | U27: 0.91081634 | V27: 2.56 | W27: 0.55966091 | X27: =RANK(W27,($W$4:$W$181),0)+COUNTIF($W$4:W27,W27)-1 -> 24 | Y27: =RANK(T27,($T$4:$T$181),0)+COUNTIF($T$4:T27,T27)-1 -> 42
A28: 172029365 | B28: ᵁᴺCTAMツ | C28: 37413149 | D28: 171300154 | E28: 16228012 | F28: 467386 | G28: 576055 | H28: 745078 | I28: 58412924 | J28: 20638886 | K28: 91799772 | L28: 22014 | M28: 1009684 | N28: 1954585 | O28: 2964269 | P28: =(211682+463137+99704)*100 -> 77452300 | Q28: 0 | R28: 1409264 | S28: -4158699 | T28: 49283375 | U28: 0.8437067 | V28: 3.75 | W28: 0.53685727 | X28: =RANK(W28,($W$4:$W$181),0)+COUNTIF($W$4:W28,W28)-1 -> 25 | Y28: =RANK(T28,($T$4:$T$181),0)+COUNTIF($T$4:T28,T28)-1 -> 59
A29: 120029911 | B29: Ħeřr Şimôñ | C29: 64051644 | D29: 1005139677 | E29: 36448559 | F29: 1048455 | G29: 1289829 | H29: 258031 | I29: 2.0195433e+08 | J29: 1.0803504e+08 | K29: 3.1778836e+08 | L29: 861398 | M29: 2540709 | N29: 6965504 | O29: 9506213 | P29: =2618*100 -> 261800 | Q29: =(326056+492691+88034+21701)*200 -> 185696400 | R29: 931073 | S29: -12047486 | T29: 164912232 | U29: 0.81658179 | V29: 1.72 | W29: 0.51893729 | X29: =RANK(W29,($W$4:$W$181),0)+COUNTIF($W$4:W29,W29)-1 -> 26 | Y29: =RANK(T29,($T$4:$T$181),0)+COUNTIF($T$4:T29,T29)-1 -> 24
A30: 171491377 | B30: ᵀᵒᴿQuyet | C30: 70418750 | D30: 522106936 | E30: 59962087 | F30: 685612 | G30: 2654441 | H30: 215112 | I30: 1.9865335e+08 | J30: 1.0640215e+08 | K30: 3.1297369e+08 | L30: 81001 | M30: 1669124 | N30: 7152182 | O30: 8821306 | P30: =(80390+380585+124632)*100 -> 58560700 | Q30: =(39531+53795+84280)*200 -> 35521200 | R30: 763236 | S30: -2468189 | T30: 159829011 | U30: 0.80456238 | V30: 0.88 | W30: 0.51067875 | X30: =RANK(W30,($W$4:$W$181),0)+COUNTIF($W$4:W30,W30)-1 -> 27 | Y30: =RANK(T30,($T$4:$T$181),0)+COUNTIF($T$4:T30,T30)-1 -> 25
A31: 176044158 | B31: メSuper Manメ | C31: 42667600 | D31: 131159590 | E31: 18119267 | F31: 479611 | G31: 666033 | H31: 841610 | I31: 76912270 | J31: 35410929 | K31: 1.2448348e+08 | L31: 25477 | M31: 746514 | N31: 2620090 | O31: 3366604 | P31: =(682721+796767+393239)*100 -> 187272700 | Q31: 0 | R31: 1872727 | S31: -4898298 | T31: 59886027 | U31: 0.77862774 | V31: 5.29 | W31: 0.48107611 | X31: =RANK(W31,($W$4:$W$181),0)+COUNTIF($W$4:W31,W31)-1 -> 28 | Y31: =RANK(T31,($T$4:$T$181),0)+COUNTIF($T$4:T31,T31)-1 -> 55
A32: 171609840 | B32: KaizerX | C32: 61633448 | D32: 587705450 | E32: 59013377 | F32: 514910 | G32: 2693175 | H32: 214022 | I32: 1.5903689e+08 | J32: 85983854 | K32: 2.5435771e+08 | L32: 3884 | M32: 807120 | N32: 5641466 | O32: 6448586 | P32: =(105160+18569)*100 -> 12372900 | Q32: =(141153+185740+59395)*200 -> 77257600 | R32: 510018 | S32: -6493909 | T32: 120901297 | U32: 0.76020913 | V32: 1.04 | W32: 0.47531995 | X32: =RANK(W32,($W$4:$W$181),0)+COUNTIF($W$4:W32,W32)-1 -> 29 | Y32: =RANK(T32,($T$4:$T$181),0)+COUNTIF($T$4:T32,T32)-1 -> 34
A33: 190550149 | B33: Lach Zielas | C33: 22930329 | D33: 37364211 | E33: 330520 | F33: 0 | G33: 16526 | H33: 0 | I33: 24455225 | J33: -25161462 | K33: 12853530 | L33: 449491 | M33: 334700 | N33: 117403 | O33: 452103 | P33: TBA | Q33: TBA | R33: 108346 | S33: 1132386 | T33: 6101114 | U33: 0.249481 | V33: -0.0043060296 | W33: 0.47466449 | X33: =RANK(W33,($W$4:$W$181),0)+COUNTIF($W$4:W33,W33)-1 -> 30 | Y33: =RANK(T33,($T$4:$T$181),0)+COUNTIF($T$4:T33,T33)-1 -> 100
A34: 172033754 | B34: Dreckschlumpf | C34: 65852776 | D34: 484872769 | E34: 50594905 | F34: 3799923 | G34: 426013 | H34: 406987 | I34: 1.9196546e+08 | J34: 1.0306481e+08 | K34: 3.0318953e+08 | L34: 1268596 | M34: 6885095 | N34: 3136709 | O34: 10021804 | P34: =(42145+170778+222458)*100 -> 43538100 | Q34: =(139012+695322+5805)*200 -> 168027800 | R34: 1280063 | S34: -7214514 | T34: 136229282 | U34: 0.70965517 | V34: 2.05 | W34: 0.44932053 | X34: =RANK(W34,($W$4:$W$181),0)+COUNTIF($W$4:W34,W34)-1 -> 31 | Y34: =RANK(T34,($T$4:$T$181),0)+COUNTIF($T$4:T34,T34)-1 -> 29
A35: 170728362 | B35: 乂 マoddi 乂 | C35: 55156572 | D35: 523973532 | E35: 27541001 | F35: 499307 | G35: 1127310 | H35: 366956 | I35: 1.5990137e+08 | J35: 86447926 | K35: 2.5565557e+08 | L35: 3072 | M35: 1189580 | N35: 4992621 | O35: 6182201 | P35: =(68191+110356+185158)*100 -> 36370500 | Q35: =(197300+529032+238187)*200 -> 192903800 | R35: 1328224 | S35: -11836533 | T35: 111755091 | U35: 0.69890013 | V35: 2.65 | W35: 0.43713145 | X35: =RANK(W35,($W$4:$W$181),0)+COUNTIF($W$4:W35,W35)-1 -> 32 | Y35: =RANK(T35,($T$4:$T$181),0)+COUNTIF($T$4:T35,T35)-1 -> 37
A36: 170866748 | B36: Tzilacatzin | C36: 68876564 | D36: 640450638 | E36: 49163028 | F36: 303979 | G36: 2306135 | H36: 508039 | I36: 2.2282587e+08 | J36: 1.1815779e+08 | K36: 3.4802611e+08 | L36: 772 | M36: 1118293 | N36: 6638068 | O36: 7756361 | P36: =(262228+256152+221290+43461)*100 -> 78313100 | Q36: =15241*200 -> 3048200 | R36: 798373 | S36: -9394127 | T36: 143944841 | U36: 0.64599699 | V36: 0.69 | W36: 0.41360357 | X36: =RANK(W36,($W$4:$W$181),0)+COUNTIF($W$4:W36,W36)-1 -> 33 | Y36: =RANK(T36,($T$4:$T$181),0)+COUNTIF($T$4:T36,T36)-1 -> 27
A37: 172041454 | B37: ᵁᴺSeckin34 | C37: 64561350 | D37: 518612647 | E37: 38875565 | F37: 680956 | G37: 1601602 | H37: 619288 | I37: 2.137132e+08 | J37: 1.1377924e+08 | K37: 3.3486579e+08 | L37: 8205 | M37: 1565179 | N37: 5857375 | O37: 7422554 | P37: 0 | Q37: =(651855+718042+210848)*200 -> 316149000 | R37: 1580745 | S37: -16223814 | T37: 132905021 | U37: 0.62188495 | V37: 2.78 | W37: 0.39689041 | X37: =RANK(W37,($W$4:$W$181),0)+COUNTIF($W$4:W37,W37)-1 -> 34 | Y37: =RANK(T37,($T$4:$T$181),0)+COUNTIF($T$4:T37,T37)-1 -> 32
A38: 169427770 | B38: ᵁᴺ Saxon | C38: 70123784 | D38: 811052722 | E38: 45025925 | F38: 745302 | G38: 1877719 | H38: 297530 | I38: 2.5354034e+08 | J38: 1.325028e+08 | K38: 3.919644e+08 | L38: 51660 | M38: 1960983 | N38: 6726324 | O38: 8687307 | P38: =(37232+23478+5077)*100 -> 6578700 | Q38: =(428201+760947+311770)*200 -> 300183600 | R38: 1567045 | S38: -11623156 | T38: 154190307 | U38: 0.60814902 | V38: 2.32 | W38: 0.39337835 | X38: =RANK(W38,($W$4:$W$181),0)+COUNTIF($W$4:W38,W38)-1 -> 35 | Y38: =RANK(T38,($T$4:$T$181),0)+COUNTIF($T$4:T38,T38)-1 -> 26
A39: 155534128 | B39: ŻŸŁÜĶ㋡ | C39: 61615659 | D39: 1106830933 | E39: 25913600 | F39: 605048 | G39: 993156 | H39: 346024 | I39: 1.7130204e+08 | J39: 92483595 | K39: 2.726859e+08 | L39: 43355 | M39: 1191311 | N39: 4739943 | O39: 5931254 | P39: =(88517+119295+123607+10929)*100 -> 34234800 | Q39: =(213875+163319+187053+27382)*200 -> 118325800 | R39: 933977 | S39: -6683348 | T39: 106720641 | U39: 0.62299689 | V39: 1.65 | W39: 0.39136838 | X39: =RANK(W39,($W$4:$W$181),0)+COUNTIF($W$4:W39,W39)-1 -> 36 | Y39: =RANK(T39,($T$4:$T$181),0)+COUNTIF($T$4:T39,T39)-1 -> 39
A40: 156479771 | B40: ᵁᴺSnowWoLF | C40: 74146500 | D40: 1686171829 | E40: 51308720 | F40: 466673 | G40: 2332096 | H40: 197094 | I40: 2.2508428e+08 | J40: 1.1923365e+08 | K40: 3.5127825e+08 | L40: 43 | M40: 824322 | N40: 6400707 | O40: 7225029 | P40: =(229719+6234)*100 -> 23595300 | Q40: =(76814+56300+7987)*200 -> 28220200 | R40: 377054 | S40: -5295874 | T40: 136257441 | U40: 0.60536187 | V40: 0.43 | W40: 0.38789034 | X40: =RANK(W40,($W$4:$W$181),0)+COUNTIF($W$4:W40,W40)-1 -> 37 | Y40: =RANK(T40,($T$4:$T$181),0)+COUNTIF($T$4:T40,T40)-1 -> 28
...

Sheet Filler Accounts
E1: Total Power | H1: Troops | L1: Requirement | M1: Dead | S1: Result
A2: ID | B2: Name | C2: Initial Power | D2: KP | E2: Pass 4 Power | F2: Pass 7 Power | G2: Final Power | H2: T3 | I2: T4 | J2: T5 | K2: Total Troops | L2: Min Req Troops Dead | M2: T4 Dead | N2: T5 Dead | O2: Pass 4 Dead | P2: Pass 7 Dead | Q2: KL Dead | R2: Total Dead | S2: %min Dead | T2: %Goal
A3: 100476820 | B3: Intersect 2 | C3: 50298006 | D3: 98443340 | E3: 50201970 | F3: 48490394 | G3: 45387954 | H3: 0 | I3: =728477+530100+530667 -> 1789244 | J3: 0 | K3: =SUM(H3:J3) -> 1789244 | L3: =K3*0.5 -> 894622 | M3: 1552710 | N3: 0 | O3: 0 | P3: 627890 | Q3: 924820 | R3: 1552710 | S3: 1.7356045 | T3: 0.78308809
A4: 169363448 | B4: ˣˢHelios | C4: 55026773 | D4: 320823351 | E4: 54738351 | F4: 46689269 | G4: 46795210 | H4: 0 | I4: =580191+425199+538327+425601 -> 1969318 | J4: 455543 | K4: =SUM(H4:J4) -> 2424861 | L4: =K4*0.5 -> 1212430.5 | M4: TBA | N4: TBA | O4: 2634 | P4: 1886228 | Q4: 39418 | R4: 1928280 | S4: 1.5904252 | T4: 0.67625518
A5: 112792310 | B5: KIM BANK | C5: 29167025 | D5: 51841755 | E5: 29258625 | F5: 29311689 | G5: 22911888 | H5: 0 | I5: =764881+608297+485605+166386 -> 2025169 | J5: 0 | K5: =SUM(H5:J5) -> 2025169 | L5: =K5*0.5 -> 1012584.5 | M5: TBA | N5: TBA | O5: 0 | P5: 33737 | Q5: 1482333 | R5: 1516070 | S5: 1.4972281 | T5: 0.58806689
A6: 172508036 | B6: Nizamfarm | C6: 20549165 | D6: 2171908 | E6: 20665014 | F6: 19815772 | G6: 20676692 | H6: 0 | I6: =314396+334148+298307 -> 946851 | J6: 0 | K6: =SUM(H6:J6) -> 946851 | L6: =K6*0.5 -> 473425.5 | M6: TBA | N6: TBA | O6: 0 | P6: 518717 | Q6: 0 | R6: 518717 | S6: 1.0956676 | T6: 0.55123365
A7: 66847214 | B7: Sweet Kit Cat | C7: 37717590 | D7: 127502569 | E7: 34736961 | F7: 36140693 | G7: 34434061 | H7: 0 | I7: =489404+408632+559806+143444 -> 1601286 | J7: 0 | K7: =SUM(H7:J7) -> 1601286 | L7: =K7*0.5 -> 800643 | M7: 804286 | N7: 0 | O7: 307829 | P7: 102679 | Q7: 393778 | R7: 804286 | S7: 1.0045501 | T7: 0.45854917
A8: 175650426 | B8: ツ ʂìʍøñ | C8: 40881326 | D8: 196112640 | E8: 41020056 | F8: 40897536 | G8: 38591423 | H8: 0 | I8: =543649+570326+502913+322102 -> 1938990 | J8: 0 | K8: =SUM(H8:J8) -> 1938990 | L8: =K8*0.5 -> 969495 | M8: 938997 | N8: 0 | O8: 180630 | P8: 295924 | Q8: 462443 | R8: 938997 | S8: 0.96854239 | T8: 0.45714551
A9: 169018140 | B9: ᶜᴸCesar82 | C9: 47494406 | D9: 137265257 | E9: 47113100 | F9: 46292116 | G9: 44908601 | H9: =8313+19994 -> 28307 | I9: =876263+993680+949437 -> 2819380 | J9: 0 | K9: =SUM(H9:J9) -> 2847687 | L9: =K9*0.5 -> 1423843.5 | M9: 1108945 | N9: 0 | O9: 85695 | P9: 365398 | Q9: 657852 | R9: 1108945 | S9: 0.77883911 | T9: 0.36821783
A10: 158392134 | B10: Daddy Prama | C10: 22796274 | D10: 44568442 | E10: 20886090 | F10: 20484906 | G10: 21023810 | H10: 0 | I10: =239884+342414+174836+48364 -> 805498 | J10: 0 | K10: =SUM(H10:J10) -> 805498 | L10: =K10*0.5 -> 402749 | M10: TBA | N10: TBA | O10: 27067 | P10: 241900 | Q10: 47716 | R10: 316683 | S10: 0.78630363 | T10: 0.36258333
A11: 109960210 | B11: LilPisontije | C11: 20175746 | D11: 3385640 | E11: 19492978 | F11: 20057756 | G11: 19312148 | H11: =1700*4 -> 6800 | I11: =298747+247256+275442 -> 821445 | J11: 0 | K11: =SUM(H11:J11) -> 828245 | L11: =K11*0.5 -> 414122.5 | M11: TBA | N11: TBA | O11: 28628 | P11: 30478 | Q11: 129693 | R11: 188799 | S11: 0.45590133 | T11: 0.21819352
A12: 79647211 | B12: BabyPisontije | C12: 28474572 | D12: 31906045 | E12: 27417805 | F12: 27268741 | G12: 27014215 | H12: =1700+1700+1700 -> 5100 | I12: =444486+408755+429916 -> 1283157 | J12: 0 | K12: =SUM(H12:J12) -> 1288257 | L12: =K12*0.5 -> 644128.5 | M12: TBA | N12: TBA | O12: 97470 | P12: 37987 | Q12: 159167 | R12: 294624 | S12: 0.45739942 | T12: 0.21697053
A13: 167637163 | B13: ・Lazy Maka・ | C13: 63421427 | D13: 452376008 | E13: 63798727 | F13: 63608527 | G13: 61414373 | H13: 0 | I13: =393198+163820+228643 -> 785661 | J13: =103358+562451+253870 -> 919679 | K13: =SUM(H13:J13) -> 1705340 | L13: =K13*0.5 -> 852670 | M13: TBA | N13: TBA | O13: 0 | P13: 67130 | Q13: 253728 | R13: 320858 | S13: 0.37629798 | T13: 0.18219477
A14: 177526978 | B14: Son of Odin2997 | C14: 72227352 | D14: 98136386 | E14: 70855324 | F14: 71722068 | G14: 73996724 | H14: 0 | I14: =338170+419624+375213 -> 1133007 | J14: =730731+286824+172000 -> 1189555 | K14: =SUM(H14:J14) -> 2322562 | L14: =K14*0.5 -> 1161281 | M14: TBA | N14: TBA | O14: 73324 | P14: 34267 | Q14: 73837 | R14: 181428 | S14: 0.15623092 | T14: 0.080029075
A15: 171945722 | B15: Jools Jnr | C15: 44011092 | D15: 60955703 | E15: 44075592 | F15: 44385865 | G15: 45064006 | H15: 0 | I15: =441093+447500+881887+336192 -> 2106672 | J15: 0 | K15: =SUM(H15:J15) -> 2106672 | L15: =K15*0.5 -> 1053336 | M15: 108697 | N15: 0 | O15: 0 | P15: 57383 | Q15: 51314 | R15: 108697 | S15: 0.10319309 | T15: 0.052830934
A16: 151360763 | B16: Laze Bobr | C16: 57175105 | D16: 105334287 | E16: 57271753 | F16: 57878627 | G16: 57662791 | H16: 0 | I16: =1140510+1693199+1222961+35264 -> 4091934 | J16: 0 | K16: =SUM(H16:J16) -> 4091934 | L16: =K16*0.5 -> 2045967 | M16: TBA | N16: TBA | O16: 0 | P16: 45904 | Q16: 102147 | R16: 148051 | S16: 0.07236236 | T16: 0.036489794
A17: 61106312 | B17: 乄Bツ1 | C17: 25171495 | D17: 134119074 | E17: 25178854 | F17: 25086310 | G17: 25245254 | H17: 0 | I17: =160617+362234+185941+12812 -> 721604 | J17: 0 | K17: =SUM(H17:J17) -> 721604 | L17: =K17*0.5 -> 360802 | M17: TBA | N17: TBA | O17: 0 | P17: 0 | Q17: 0 | R17: 0 | S17: 0 | T17: 0
A18: 145948216 | B18: LOSANT BORED | C18: 40400817 | D18: 61245328 | E18: 39258409 | F18: 39655458 | G18: 36539360 | H18: 0 | I18: 0 | J18: 0 | K18: =SUM(H18:J18) -> 0 | L18: =K18*0.5 -> 0 | M18: TBA | N18: TBA | O18: 24874 | P18: 154597 | Q18: 756268 | R18: 935739 | S18: 0 | T18: 0 | U18: no reply
A19: 157398284 | B19: Фарм 2016 | C19: 25342469 | D19: 4812381 | E19: 25666219 | F19: 25823693 | G19: 25942593 | H19: =3200+1700+3280+5509 -> 13689 | I19: =743864+711707+775325+62400 -> 2293296 | J19: 0 | K19: =SUM(H19:J19) -> 2306985 | L19: =K19*0.5 -> 1153492.5 | M19: TBA | N19: TBA | O19: 0 | P19: 0 | Q19: 0 | R19: 0 | S19: 0 | T19: 0
R21: =SUM(R3:R19) -> 10862884

Sheet Mid Review Report
A1: Mid Review Report (31/12 - 6/1 2025/2026)
