Workbook

Sheet Dashboard
A1: Resource | B1: Total In | C1: Total Out | D1: Current Balance
A2: Food | B2: =SUMIFS(Transactions!D:D, Transactions!H:H, "Incoming") -> 13895875350 | C2: =SUMIFS(Transactions!D:D, Transactions!H:H, "Outgoing") -> 6300000000 | D2: =B2-C2-368987435 -> 7226887915
A3: Wood | B3: =SUMIFS(Transactions!E:E, Transactions!H:H, "Incoming") -> 16339304199 | C3: =SUMIFS(Transactions!E:E, Transactions!H:H, "Outgoing") -> 9950000000 | D3: =B3-C3-384959130 -> 6004345069
A4: Stone | B4: =SUMIFS(Transactions!F:F, Transactions!H:H, "Incoming") -> 11298197983 | C4: =SUMIFS(Transactions!F:F, Transactions!H:H, "Outgoing") -> 6600000000 | D4: =B4-C4-1106524607 -> 3591673376
A5: Gold | B5: =SUMIFS(Transactions!G:G, Transactions!H:H, "Incoming") -> 7158632935 | C5: =SUMIFS(Transactions!G:G, Transactions!H:H, "Outgoing") -> 5220000000 | D5: =B5-C5-402782585 -> 1535850350
A9: ID | B9: NAME | C9: FOOD | D9: WOOD | E9: STONE | F9: GOLD | G9: TOTAL RSS
A10: 2463403 | B10: Heliøsツ | C10: =SUMIFS(Transactions!D:D,Transactions!B:B, "Heliøsツ",Transactions!H:H,"Incoming") -> 32146666 | D10: =SUMIFS(Transactions!E:E,Transactions!B:B, "Heliøsツ",Transactions!H:H,"Incoming") -> 42946666 | E10: =SUMIFS(Transactions!F:F,Transactions!B:B, "Heliøsツ",Transactions!H:H,"Incoming") -> 24106666 | F10: =SUMIFS(Transactions!G:G,Transactions!B:B, "Heliøsツ",Transactions!H:H,"Incoming") -> 10800001 | G10: =SUM(C10:F10) -> 109999999
A11: 11726598 | B11: Lazy Cat ツ | C11: =SUMIFS(Transactions!D:D,Transactions!B:B, "Lazy Cat ツ",Transactions!H:H,"Incoming") -> 54480001 | D11: =SUMIFS(Transactions!E:E,Transactions!B:B, "Lazy Cat ツ",Transactions!H:H,"Incoming") -> 3680000 | E11: =SUMIFS(Transactions!F:F,Transactions!B:B, "Lazy Cat ツ",Transactions!H:H,"Incoming") -> 4600000 | F11: =SUMIFS(Transactions!G:G,Transactions!B:B, "Lazy Cat ツ",Transactions!H:H,"Incoming") -> 5520000 | G11: =SUM(C11:F11) -> 68280001
A12: 171604682 | B12: Łørd Ᵽraмa | C12: =SUMIFS(Transactions!D:D,Transactions!B:B, "Łørd Ᵽraмa",Transactions!H:H,"Incoming") -> 63416000 | D12: =SUMIFS(Transactions!E:E,Transactions!B:B, "Łørd Ᵽraмa",Transactions!H:H,"Incoming") -> 64878000 | E12: =SUMIFS(Transactions!F:F,Transactions!B:B, "Łørd Ᵽraмa",Transactions!H:H,"Incoming") -> 44602000 | F12: =SUMIFS(Transactions!G:G,Transactions!B:B, "Łørd Ᵽraмa",Transactions!H:H,"Incoming") -> 37904000 | G12: =SUM(C12:F12) -> 210800000
A13: 156339380 | B13: 會 ᴋᴀʏ シ | C13: =SUMIFS(Transactions!D:D,Transactions!B:B, "會 ᴋᴀʏ シ",Transactions!H:H,"Incoming") -> 70000000 | D13: =SUMIFS(Transactions!E:E,Transactions!B:B, "會 ᴋᴀʏ シ",Transactions!H:H,"Incoming") -> 70000000 | E13: =SUMIFS(Transactions!F:F,Transactions!B:B, "會 ᴋᴀʏ シ",Transactions!H:H,"Incoming") -> 70000000 | F13: =SUMIFS(Transactions!G:G,Transactions!B:B, "會 ᴋᴀʏ シ",Transactions!H:H,"Incoming") -> 70000000 | G13: =SUM(C13:F13) -> 280000000
A14: 167637163 | B14: ・Maka・ | C14: =SUMIFS(Transactions!D:D,Transactions!B:B, "・Maka・",Transactions!H:H,"Incoming") -> 87621720 | D14: =SUMIFS(Transactions!E:E,Transactions!B:B, "・Maka・",Transactions!H:H,"Incoming") -> 60621720 | E14: =SUMIFS(Transactions!F:F,Transactions!B:B, "・Maka・",Transactions!H:H,"Incoming") -> 55301720 | F14: =SUMIFS(Transactions!G:G,Transactions!B:B, "・Maka・",Transactions!H:H,"Incoming") -> 28180040 | G14: =SUM(C14:F14) -> 231725200
A15: 169446444 | B15: lazy Liwen 寳 | C15: =SUMIFS(Transactions!D:D,Transactions!B:B, "lazy Liwen 寳",Transactions!H:H,"Incoming") -> 15525736 | D15: =SUMIFS(Transactions!E:E,Transactions!B:B, "lazy Liwen 寳",Transactions!H:H,"Incoming") -> 15525736 | E15: =SUMIFS(Transactions!F:F,Transactions!B:B, "lazy Liwen 寳",Transactions!H:H,"Incoming") -> 17606776 | F15: =SUMIFS(Transactions!G:G,Transactions!B:B, "lazy Liwen 寳",Transactions!H:H,"Incoming") -> 13741976 | G15: =SUM(C15:F15) -> 62400224
A16: 169461237 | B16: Aurionツ | C16: =SUMIFS(Transactions!D:D,Transactions!B:B, "Aurionツ",Transactions!H:H,"Incoming") -> 715803831 | D16: =SUMIFS(Transactions!E:E,Transactions!B:B, "Aurionツ",Transactions!H:H,"Incoming") -> 369941389 | E16: =SUMIFS(Transactions!F:F,Transactions!B:B, "Aurionツ",Transactions!H:H,"Incoming") -> 483669060 | F16: =SUMIFS(Transactions!G:G,Transactions!B:B, "Aurionツ",Transactions!H:H,"Incoming") -> 271669772 | G16: =SUM(C16:F16) -> 1841084052
A17: 145408006 | B17: Adam23 | C17: =SUMIFS(Transactions!D:D,Transactions!B:B, "Adam23",Transactions!H:H,"Incoming") -> 0 | D17: =SUMIFS(Transactions!E:E,Transactions!B:B, "Adam23",Transactions!H:H,"Incoming") -> 60000000 | E17: =SUMIFS(Transactions!F:F,Transactions!B:B, "Adam23",Transactions!H:H,"Incoming") -> 10000000 | F17: =SUMIFS(Transactions!G:G,Transactions!B:B, "Adam23",Transactions!H:H,"Incoming") -> 0 | G17: =SUM(C17:F17) -> 70000000
A18: 63222201 | B18: AmiralMaximus | C18: =SUMIFS(Transactions!D:D,Transactions!B:B, "AmiralMaximus",Transactions!H:H,"Incoming") -> 0 | D18: =SUMIFS(Transactions!E:E,Transactions!B:B, "AmiralMaximus",Transactions!H:H,"Incoming") -> 0 | E18: =SUMIFS(Transactions!F:F,Transactions!B:B, "AmiralMaximus",Transactions!H:H,"Incoming") -> 0 | F18: =SUMIFS(Transactions!G:G,Transactions!B:B, "AmiralMaximus",Transactions!H:H,"Incoming") -> 0 | G18: =SUM(C18:F18) -> 0
A19: 64010776 | B19: ᵀᶜ Tequila | C19: =SUMIFS(Transactions!D:D,Transactions!B:B, "ᵀᶜ Tequila",Transactions!H:H,"Incoming") -> 22880000 | D19: =SUMIFS(Transactions!E:E,Transactions!B:B, "ᵀᶜ Tequila",Transactions!H:H,"Incoming") -> 22880000 | E19: =SUMIFS(Transactions!F:F,Transactions!B:B, "ᵀᶜ Tequila",Transactions!H:H,"Incoming") -> 27884800 | F19: =SUMIFS(Transactions!G:G,Transactions!B:B, "ᵀᶜ Tequila",Transactions!H:H,"Incoming") -> 19200000 | G19: =SUM(C19:F19) -> 92844800
A20: 171934536 | B20: FromKiev1122 | C20: =SUMIFS(Transactions!D:D,Transactions!B:B, "FromKiev1122",Transactions!H:H,"Incoming") -> 30000000 | D20: =SUMIFS(Transactions!E:E,Transactions!B:B, "FromKiev1122",Transactions!H:H,"Incoming") -> 30000000 | E20: =SUMIFS(Transactions!F:F,Transactions!B:B, "FromKiev1122",Transactions!H:H,"Incoming") -> 10000000 | F20: =SUMIFS(Transactions!G:G,Transactions!B:B, "FromKiev1122",Transactions!H:H,"Incoming") -> 10000000 | G20: =SUM(C20:F20) -> 80000000
A21: 115125159 | B21: ᵂAᴿ Demon | C21: =SUMIFS(Transactions!D:D,Transactions!B:B, "ᵂAᴿ Demon",Transactions!H:H,"Incoming") -> 0 | D21: =SUMIFS(Transactions!E:E,Transactions!B:B, "ᵂAᴿ Demon",Transactions!H:H,"Incoming") -> 0 | E21: =SUMIFS(Transactions!F:F,Transactions!B:B, "ᵂAᴿ Demon",Transactions!H:H,"Incoming") -> 0 | F21: =SUMIFS(Transactions!G:G,Transactions!B:B, "ᵂAᴿ Demon",Transactions!H:H,"Incoming") -> 0 | G21: =SUM(C21:F21) -> 0
A22: 62691192 | B22: Siyempi | C22: =SUMIFS(Transactions!D:D,Transactions!B:B, "Siyempi",Transactions!H:H,"Incoming") -> 19136000 | D22: =SUMIFS(Transactions!E:E,Transactions!B:B, "Siyempi",Transactions!H:H,"Incoming") -> 19258880 | E22: =SUMIFS(Transactions!F:F,Transactions!B:B, "Siyempi",Transactions!H:H,"Incoming") -> 38400000 | F22: =SUMIFS(Transactions!G:G,Transactions!B:B, "Siyempi",Transactions!H:H,"Incoming") -> 18400000 | G22: =SUM(C22:F22) -> 95194880
A23: 144060837 | B23: 义CHRYS义 | C23: =SUMIFS(Transactions!D:D,Transactions!B:B, "义CHRYS义",Transactions!H:H,"Incoming") -> 4962467 | D23: =SUMIFS(Transactions!E:E,Transactions!B:B, "义CHRYS义",Transactions!H:H,"Incoming") -> 11969692 | E23: =SUMIFS(Transactions!F:F,Transactions!B:B, "义CHRYS义",Transactions!H:H,"Incoming") -> 45827840 | F23: =SUMIFS(Transactions!G:G,Transactions!B:B, "义CHRYS义",Transactions!H:H,"Incoming") -> 0 | G23: =SUM(C23:F23) -> 62759999
A24: 62576249 | B24: ﾒUğurﾒ | C24: =SUMIFS(Transactions!D:D,Transactions!B:B, "ﾒUğurﾒ",Transactions!H:H,"Incoming") -> 9200000 | D24: =SUMIFS(Transactions!E:E,Transactions!B:B, "ﾒUğurﾒ",Transactions!H:H,"Incoming") -> 9200000 | E24: =SUMIFS(Transactions!F:F,Transactions!B:B, "ﾒUğurﾒ",Transactions!H:H,"Incoming") -> 217920000 | F24: =SUMIFS(Transactions!G:G,Transactions!B:B, "ﾒUğurﾒ",Transactions!H:H,"Incoming") -> 3680000 | G24: =SUM(C24:F24) -> 240000000
A25: 86936270 | B25: Tekno23 | C25: =SUMIFS(Transactions!D:D,Transactions!B:B, "Tekno23",Transactions!H:H,"Incoming") -> 0 | D25: =SUMIFS(Transactions!E:E,Transactions!B:B, "Tekno23",Transactions!H:H,"Incoming") -> 0 | E25: =SUMIFS(Transactions!F:F,Transactions!B:B, "Tekno23",Transactions!H:H,"Incoming") -> 0 | F25: =SUMIFS(Transactions!G:G,Transactions!B:B, "Tekno23",Transactions!H:H,"Incoming") -> 0 | G25: =SUM(C25:F25) -> 0
A26: 138715530 | B26: ᵀᴺ Yakoo | C26: =SUMIFS(Transactions!D:D,Transactions!B:B, "ᵀᴺ Yakoo",Transactions!H:H,"Incoming") -> 40000000 | D26: =SUMIFS(Transactions!E:E,Transactions!B:B, "ᵀᴺ Yakoo",Transactions!H:H,"Incoming") -> 40000000 | E26: =SUMIFS(Transactions!F:F,Transactions!B:B, "ᵀᴺ Yakoo",Transactions!H:H,"Incoming") -> 40000000 | F26: =SUMIFS(Transactions!G:G,Transactions!B:B, "ᵀᴺ Yakoo",Transactions!H:H,"Incoming") -> 30000000 | G26: =SUM(C26:F26) -> 150000000
A27: 63168658 | B27: Kᴀᴋᴀsʜɪ | C27: =SUMIFS(Transactions!D:D,Transactions!B:B, "Kᴀᴋᴀsʜɪ",Transactions!H:H,"Incoming") -> 0 | D27: =SUMIFS(Transactions!E:E,Transactions!B:B, "Kᴀᴋᴀsʜɪ",Transactions!H:H,"Incoming") -> 0 | E27: =SUMIFS(Transactions!F:F,Transactions!B:B, "Kᴀᴋᴀsʜɪ",Transactions!H:H,"Incoming") -> 0 | F27: =SUMIFS(Transactions!G:G,Transactions!B:B, "Kᴀᴋᴀsʜɪ",Transactions!H:H,"Incoming") -> 0 | G27: =SUM(C27:F27) -> 0
A28: 171879011 | B28: Urkel94 | C28: =SUMIFS(Transactions!D:D,Transactions!B:B, "Urkel94",Transactions!H:H,"Incoming") -> 64998880 | D28: =SUMIFS(Transactions!E:E,Transactions!B:B, "Urkel94",Transactions!H:H,"Incoming") -> 65001118 | E28: =SUMIFS(Transactions!F:F,Transactions!B:B, "Urkel94",Transactions!H:H,"Incoming") -> 365001118 | F28: =SUMIFS(Transactions!G:G,Transactions!B:B, "Urkel94",Transactions!H:H,"Incoming") -> 64998882 | G28: =SUM(C28:F28) -> 559999998
A29: 146164713 | B29: 爻WarLock爻 | C29: =SUMIFS(Transactions!D:D,Transactions!B:B, "爻WarLock爻",Transactions!H:H,"Incoming") -> 0 | D29: =SUMIFS(Transactions!E:E,Transactions!B:B, "爻WarLock爻",Transactions!H:H,"Incoming") -> 0 | E29: =SUMIFS(Transactions!F:F,Transactions!B:B, "爻WarLock爻",Transactions!H:H,"Incoming") -> 0 | F29: =SUMIFS(Transactions!G:G,Transactions!B:B, "爻WarLock爻",Transactions!H:H,"Incoming") -> 0 | G29: =SUM(C29:F29) -> 0
A30: 71152824 | B30: FIREWoLF | C30: =SUMIFS(Transactions!D:D,Transactions!B:B, "FIREWoLF",Transactions!H:H,"Incoming") -> 0 | D30: =SUMIFS(Transactions!E:E,Transactions!B:B, "FIREWoLF",Transactions!H:H,"Incoming") -> 0 | E30: =SUMIFS(Transactions!F:F,Transactions!B:B, "FIREWoLF",Transactions!H:H,"Incoming") -> 0 | F30: =SUMIFS(Transactions!G:G,Transactions!B:B, "FIREWoLF",Transactions!H:H,"Incoming") -> 0 | G30: =SUM(C30:F30) -> 0
A31: 11409556 | B31: Enes 33 | C31: =SUMIFS(Transactions!D:D,Transactions!B:B, "Enes 33",Transactions!H:H,"Incoming") -> 0 | D31: =SUMIFS(Transactions!E:E,Transactions!B:B, "Enes 33",Transactions!H:H,"Incoming") -> 0 | E31: =SUMIFS(Transactions!F:F,Transactions!B:B, "Enes 33",Transactions!H:H,"Incoming") -> 0 | F31: =SUMIFS(Transactions!G:G,Transactions!B:B, "Enes 33",Transactions!H:H,"Incoming") -> 0 | G31: =SUM(C31:F31) -> 0
A32: 169247313 | B32: ƝÎ乙ĀⱮ | C32: =SUMIFS(Transactions!D:D,Transactions!B:B, "ƝÎ乙ĀⱮ",Transactions!H:H,"Incoming") -> 20920000 | D32: =SUMIFS(Transactions!E:E,Transactions!B:B, "ƝÎ乙ĀⱮ",Transactions!H:H,"Incoming") -> 19320000 | E32: =SUMIFS(Transactions!F:F,Transactions!B:B, "ƝÎ乙ĀⱮ",Transactions!H:H,"Incoming") -> 21160000 | F32: =SUMIFS(Transactions!G:G,Transactions!B:B, "ƝÎ乙ĀⱮ",Transactions!H:H,"Incoming") -> 13800000 | G32: =SUM(C32:F32) -> 75200000
A33: 14572491 | B33: LAZY BOOND | C33: =SUMIFS(Transactions!D:D,Transactions!B:B, "LAZY BOOND",Transactions!H:H,"Incoming") -> 50000000 | D33: =SUMIFS(Transactions!E:E,Transactions!B:B, "LAZY BOOND",Transactions!H:H,"Incoming") -> 20000000 | E33: =SUMIFS(Transactions!F:F,Transactions!B:B, "LAZY BOOND",Transactions!H:H,"Incoming") -> 20000000 | F33: =SUMIFS(Transactions!G:G,Transactions!B:B, "LAZY BOOND",Transactions!H:H,"Incoming") -> 20000000 | G33: =SUM(C33:F33) -> 110000000
A34: 144109282 | B34: RiP2016 | C34: =SUMIFS(Transactions!D:D,Transactions!B:B, "RiP2016",Transactions!H:H,"Incoming") -> 384000000 | D34: =SUMIFS(Transactions!E:E,Transactions!B:B, "RiP2016",Transactions!H:H,"Incoming") -> 64000000 | E34: =SUMIFS(Transactions!F:F,Transactions!B:B, "RiP2016",Transactions!H:H,"Incoming") -> 142000000 | F34: =SUMIFS(Transactions!G:G,Transactions!B:B, "RiP2016",Transactions!H:H,"Incoming") -> 622400000 | G34: =SUM(C34:F34) -> 1212400000
A35: 144048157 | B35: J Pangestu | C35: =SUMIFS(Transactions!D:D,Transactions!B:B, "J Pangestu",Transactions!H:H,"Incoming") -> 0 | D35: =SUMIFS(Transactions!E:E,Transactions!B:B, "J Pangestu",Transactions!H:H,"Incoming") -> 0 | E35: =SUMIFS(Transactions!F:F,Transactions!B:B, "J Pangestu",Transactions!H:H,"Incoming") -> 0 | F35: =SUMIFS(Transactions!G:G,Transactions!B:B, "J Pangestu",Transactions!H:H,"Incoming") -> 0 | G35: =SUM(C35:F35) -> 0
A36: 136378574 | B36: Arktos | C36: =SUMIFS(Transactions!D:D,Transactions!B:B, "Arktos",Transactions!H:H,"Incoming") -> 0 | D36: =SUMIFS(Transactions!E:E,Transactions!B:B, "Arktos",Transactions!H:H,"Incoming") -> 0 | E36: =SUMIFS(Transactions!F:F,Transactions!B:B, "Arktos",Transactions!H:H,"Incoming") -> 0 | F36: =SUMIFS(Transactions!G:G,Transactions!B:B, "Arktos",Transactions!H:H,"Incoming") -> 0 | G36: =SUM(C36:F36) -> 0
A37: 171827401 | B37: King ᶠʳʸ | C37: =SUMIFS(Transactions!D:D,Transactions!B:B, "King ᶠʳʸ",Transactions!H:H,"Incoming") -> 0 | D37: =SUMIFS(Transactions!E:E,Transactions!B:B, "King ᶠʳʸ",Transactions!H:H,"Incoming") -> 0 | E37: =SUMIFS(Transactions!F:F,Transactions!B:B, "King ᶠʳʸ",Transactions!H:H,"Incoming") -> 0 | F37: =SUMIFS(Transactions!G:G,Transactions!B:B, "King ᶠʳʸ",Transactions!H:H,"Incoming") -> 0 | G37: =SUM(C37:F37) -> 0
A38: 171503078 | B38: メCalメ | C38: =SUMIFS(Transactions!D:D,Transactions!B:B, "メCalメ",Transactions!H:H,"Incoming") -> 174720000 | D38: =SUMIFS(Transactions!E:E,Transactions!B:B, "メCalメ",Transactions!H:H,"Incoming") -> 99320000 | E38: =SUMIFS(Transactions!F:F,Transactions!B:B, "メCalメ",Transactions!H:H,"Incoming") -> 78720000 | F38: =SUMIFS(Transactions!G:G,Transactions!B:B, "メCalメ",Transactions!H:H,"Incoming") -> 38199600 | G38: =SUM(C38:F38) -> 390959600
A39: 171798243 | B39: CrazyLady2 | C39: =SUMIFS(Transactions!D:D,Transactions!B:B, "CrazyLady2",Transactions!H:H,"Incoming") -> 221407717 | D39: =SUMIFS(Transactions!E:E,Transactions!B:B, "CrazyLady2",Transactions!H:H,"Incoming") -> 349241883 | E39: =SUMIFS(Transactions!F:F,Transactions!B:B, "CrazyLady2",Transactions!H:H,"Incoming") -> 186223529 | F39: =SUMIFS(Transactions!G:G,Transactions!B:B, "CrazyLady2",Transactions!H:H,"Incoming") -> 66243708 | G39: =SUM(C39:F39) -> 823116837
A40: 140009179 | B40: Herakles ツ | C40: =SUMIFS(Transactions!D:D,Transactions!B:B, "Herakles ツ",Transactions!H:H,"Incoming") -> 20000000 | D40: =SUMIFS(Transactions!E:E,Transactions!B:B, "Herakles ツ",Transactions!H:H,"Incoming") -> 30000000 | E40: =SUMIFS(Transactions!F:F,Transactions!B:B, "Herakles ツ",Transactions!H:H,"Incoming") -> 18210089 | F40: =SUMIFS(Transactions!G:G,Transactions!B:B, "Herakles ツ",Transactions!H:H,"Incoming") -> 5143595 | G40: =SUM(C40:F40) -> 73353684
A41: 171983336 | B41: AzeM | C41: =SUMIFS(Transactions!D:D,Transactions!B:B, "AzeM",Transactions!H:H,"Incoming") -> 64600000 | D41: =SUMIFS(Transactions!E:E,Transactions!B:B, "AzeM",Transactions!H:H,"Incoming") -> 64600000 | E41: =SUMIFS(Transactions!F:F,Transactions!B:B, "AzeM",Transactions!H:H,"Incoming") -> 64600000 | F41: =SUMIFS(Transactions!G:G,Transactions!B:B, "AzeM",Transactions!H:H,"Incoming") -> 64600000 | G41: =SUM(C41:F41) -> 258400000
A42: 145056169 | B42: Grimm48 | C42: =SUMIFS(Transactions!D:D,Transactions!B:B, "Grimm48",Transactions!H:H,"Incoming") -> 20009600 | D42: =SUMIFS(Transactions!E:E,Transactions!B:B, "Grimm48",Transactions!H:H,"Incoming") -> 20009600 | E42: =SUMIFS(Transactions!F:F,Transactions!B:B, "Grimm48",Transactions!H:H,"Incoming") -> 70009600 | F42: =SUMIFS(Transactions!G:G,Transactions!B:B, "Grimm48",Transactions!H:H,"Incoming") -> 30009600 | G42: =SUM(C42:F42) -> 140038400
A43: 120029911 | B43: Ħeřr Şimôñ | C43: =SUMIFS(Transactions!D:D,Transactions!B:B, "Ħeřr Şimôñ",Transactions!H:H,"Incoming") -> 17572000 | D43: =SUMIFS(Transactions!E:E,Transactions!B:B, "Ħeřr Şimôñ",Transactions!H:H,"Incoming") -> 17572000 | E43: =SUMIFS(Transactions!F:F,Transactions!B:B, "Ħeřr Şimôñ",Transactions!H:H,"Incoming") -> 16348000 | F43: =SUMIFS(Transactions!G:G,Transactions!B:B, "Ħeřr Şimôñ",Transactions!H:H,"Incoming") -> 7708000 | G43: =SUM(C43:F43) -> 59200000
...

Sheet Transactions
A1: Date | B1: Player Nickname | C1: Source / Reason | D1: Food | E1: Wood | F1: Stone | G1: Gold | H1: Type | I1: Notes | J1: Colonne 1
A2: 45879 | B2: Aurionツ | C2: Starting balance | D2: 715803831 | E2: 369941389 | F2: 483669060 | G2: 114680560 | H2: Incoming | I2: Initial stock pile
A3: 45879 | B3: 乄Muhtarツ | C3: Penalty | D3: 15152000 | E3: 12208000 | F3: 14480000 | G3: 13680000 | H3: Incoming
A4: 45879 | B4: roimme | C4: Penalty | D4: 10000000 | E4: 10000000 | F4: 10000000 | G4: 10000000 | H4: Incoming
A5: 45879 | B5: SIJUGUL GORAT | C5: Voluntarily Contributions | D5: 20000000 | E5: 10000000 | F5: 10000000 | G5: 10000000 | H5: Incoming
A6: 45879 | B6: ᴱᴿ RKing79 | C6: Penalty | D6: 50000000 | E6: 50000000 | F6: 47360000 | G6: 47360000 | H6: Incoming
A7: 45879 | B7: Lord Valkorion | C7: Penalty | D7: =31472000+128800 -> 31600800 | E7: =31472000+128800 -> 31600800 | F7: =31472000+128800 -> 31600800 | G7: 31600800 | H7: Incoming
A8: 45879 | B8: TitanMARU | C8: Penalty | D8: 3992729 | E8: 15299947 | F8: 2811500 | H8: Incoming
A9: 45879 | B9: yamen Di | C9: Penalty | D9: 20000000 | E9: 40000000 | F9: 20000000 | G9: 10000000 | H9: Incoming
A10: 45879 | B10: DEHA DEVRAN | C10: Penalty | D10: 10000000 | E10: =5972144+9199080 -> 15171224 | F10: 20000000 | G10: 10000000 | H10: Incoming
A11: 45879 | B11: СЕНАТОР | C11: Penalty | D11: 20000000 | E11: 20000000 | F11: 10000000 | G11: 10000000 | H11: Incoming
A12: 45880 | B12: sd mique | C12: Penalty | D12: =38640+9936000+9936000+9200000+10000000+1840000 -> 40950640 | E12: =38640+40000000+1840000 -> 41878640 | F12: =38640+40000000+1840000 -> 41878640 | G12: =38640+40000000+1840000 -> 41878640 | H12: Incoming
A13: 45883 | B13: Fabregas1533 | C13: Penalty | D13: 900000 | E13: 900000 | F13: 900000 | G13: 900000 | H13: Incoming
A14: 45883 | B14: Adam23 | C14: Penalty | E14: 30000000 | H14: Incoming
A15: 45884 | B15: Adam23 | C15: Penalty | F15: 10000000 | H15: Incoming
A16: 45886 | B16: LAZY BOOND | C16: Penalty | D16: 50000000 | E16: 20000000 | F16: 20000000 | G16: 20000000 | H16: Incoming
A17: 45886 | B17: ᴴᵘⁿBéo | C17: Penalty | D17: 150000000 | E17: 80000000 | F17: 50000000 | G17: 20000000 | H17: Incoming
A18: 45886 | B18: Heliøsツ | C18: Penalty | D18: 20000000 | E18: 30000000 | F18: 10000000 | H18: Incoming
A19: 45886 | B19: dilli | C19: U97 weekly contribution | D19: 10000000 | E19: 4600000 | F19: 2300000 | G19: 2300000 | H19: Incoming
A20: 45886 | B20: Lord Valkorion | C20: U97 weekly contribution | D20: 20000000 | E20: 20000000 | F20: 20000000 | G20: 20000000 | H20: Incoming
A21: 45886 | B21: 义Destroyer义 | C21: U97 weekly contribution | D21: 14600000 | E21: 14600000 | F21: 15400000 | G21: 14600000 | H21: Incoming
A22: 45886 | B22: AzeM | C22: U97 weekly contribution | D22: 14600000 | E22: 14600000 | F22: 14600000 | G22: 14600000 | H22: Incoming
A23: 45887 | B23: Adam23 | C23: U97 weekly contribution | E23: 30000000 | H23: Incoming
A24: 45887 | B24: ᵂʷ Sandman シ | C24: U97 weekly contribution | D24: 10000000 | E24: 10000000 | F24: 6440000 | G24: 2760000 | H24: Incoming
A25: 45887 | B25: Northernman | C25: U97 weekly contribution | G25: 20000000 | H25: Incoming
A26: 45887 | B26: Dreckschlumpf | C26: U97 weekly contribution | E26: 50000000 | F26: 10000000 | G26: 10000000 | H26: Incoming
A27: 45887 | B27: Roki Balboy | C27: U97 weekly contribution | E27: 10000000 | F27: 10000000 | H27: Incoming
A28: 45887 | B28: RiP2016 | C28: U97 weekly contribution | E28: 10000000 | H28: Incoming
A29: 45887 | B29: GAGS | C29: U97 weekly contribution | D29: 20000000 | E29: 20000000 | F29: 20000000 | G29: 20000000 | H29: Incoming
A30: 45887 | B30: Łørd Ᵽraмa | C30: U97 weekly contribution | D30: 5200000 | E30: 5200000 | F30: 5200000 | G30: 5200000 | H30: Incoming
A31: 45887 | B31: Тiамат 义 | C31: U97 weekly contribution | G31: 20000000 | H31: Incoming
A32: 45887 | B32: ﾒUğurﾒ | C32: U97 weekly contribution | F32: 20000000 | H32: Incoming
A33: 45887 | B33: メSuper Manメ | C33: U97 weekly contribution | D33: 20000000 | E33: 20000000 | F33: 20000000 | G33: 20000000 | H33: Incoming
A34: 45887 | B34: 㐅 Kookie | C34: U97 weekly contribution | E34: 73500000 | H34: Incoming
A35: 45887 | B35: NT ĐVL1 | C35: U97 weekly contribution | D35: 8000000 | E35: 4000000 | F35: 4000000 | G35: 4000000 | H35: Incoming
A36: 45887 | B36: FromKiev1122 | C36: U97 weekly contribution | D36: 10000000 | E36: 10000000 | H36: Incoming
A37: 45887 | B37: Siyempi | C37: U97 weekly contribution | D37: 4600000 | E37: 4600000 | F37: 4600000 | G37: 4600000 | H37: Incoming
A38: 45887 | B38: DompfX | C38: U97 weekly contribution | D38: 4600000 | E38: 5400000 | F38: 5400000 | G38: 4600000 | H38: Incoming
A39: 45887 | B39: 乄jacony乄 | C39: U97 weekly contribution | D39: 4600000 | E39: 9200000 | F39: 4600000 | G39: 4600000 | H39: Incoming
A40: 45887 | B40: Ƀłøømɇɍ | C40: U97 weekly contribution | D40: 20000000 | F40: 20000000 | G40: 20000000 | H40: Incoming
...

Sheet Weekly Contribution
A3: ID | B3: Name | C3: Food | D3: Wood | E3: Stone | F3: Gold | G3: Week Contribution | H3: Total Contribution
A4: 171679053 | B4: dilli | C4: 3036000 | D4: 3036000 | E4: 3036000 | F4: 1012000 | G4: =sum(C4:F4) -> 10120000 | H4: =VLOOKUP(A4,Dashboard!A:G,7,FALSE) -> 102460000
A5: 62576249 | B5: ﾒUğurﾒ | E5: 10000000 | G5: =sum(C5:F5) -> 10000000 | H5: =VLOOKUP(A5,Dashboard!A:G,7,FALSE) -> 240000000
A6: 171697263 | B6: ᵁᴺFiLLer97 | D6: 60000000 | G6: =sum(C6:F6) -> 60000000 | H6: =VLOOKUP(A6,Dashboard!A:G,7,FALSE) -> 606794789
A7: 172033754 | B7: Dreckschlumpf | C7: 1840000 | D7: 3560000 | E7: 1840000 | F7: 2760000 | G7: =sum(C7:F7) -> 10000000 | H7: =VLOOKUP(A7,Dashboard!A:G,7,FALSE) -> 930794163
A8: 169427770 | B8: SAX0N | C8: 2760000 | D8: 23560000 | E8: 1840000 | F8: 1840000 | G8: =sum(C8:F8) -> 30000000 | H8: =VLOOKUP(A8,Dashboard!A:G,7,FALSE) -> 278400000
A9: 169247313 | B9: ƝÎ乙ĀⱮ | C9: 1840000 | D9: 1840000 | E9: 2760000 | F9: 2760000 | G9: =sum(C9:F9) -> 9200000 | H9: =VLOOKUP(A9,Dashboard!A:G,7,FALSE) -> 75200000
A10: 167614515 | B10: ᵂʷ Jools シ | C10: 2760000 | D10: 2760000 | E10: 2760000 | F10: 920000 | G10: =sum(C10:F10) -> 9200000 | H10: =VLOOKUP(A10,Dashboard!A:G,7,FALSE) -> 73600000
A11: 64966340 | B11: Pisontije | C11: 10000000 | D11: 10000000 | E11: 10000000 | F11: 10000000 | G11: =sum(C11:F11) -> 40000000 | H11: =VLOOKUP(A11,Dashboard!A:G,7,FALSE) -> 184600000
A12: 167637163 | B12: ・Maka・ | C12: 2208000 | D12: 2208000 | E12: 3128000 | F12: 3128000 | G12: =sum(C12:F12) -> 10672000 | H12: =VLOOKUP(A12,Dashboard!A:G,7,FALSE) -> 231725200
A13: 170708608 | B13: OkBanSeChet | C13: 10000000 | D13: 10000000 | E13: 10000000 | G13: =sum(C13:F13) -> 30000000 | H13: =VLOOKUP(A13,Dashboard!A:G,7,FALSE) -> 131840000
A14: 171503078 | B14: メCalメ | C14: 30000000 | D14: 2760000 | E14: 1840000 | F14: 1840000 | G14: =sum(C14:F14) -> 36440000 | H14: =VLOOKUP(A14,Dashboard!A:G,7,FALSE) -> 390959600
A15: 168091444 | B15: ᵁᴺOhanaツ | C15: 3680000 | D15: 3680000 | E15: 5520000 | F15: 5520000 | G15: =sum(C15:F15) -> 18400000 | H15: =VLOOKUP(A15,Dashboard!A:G,7,FALSE) -> 235864000
A16: 98107237 | B16: 亗 Intersect | C16: 20000000 | G16: =sum(C16:F16) -> 20000000 | H16: =VLOOKUP(A16,Dashboard!A:G,7,FALSE) -> 330000000
A17: 171491377 | B17: ᵀᵒᴿQuyet | C17: 10000000 | D17: 10000000 | E17: 10000000 | F17: 10000000 | G17: =sum(C17:F17) -> 40000000 | H17: =VLOOKUP(A17,Dashboard!A:G,7,FALSE) -> 181132000
A18: 176044158 | B18: メSuper Manメ | C18: 10000000 | D18: 10000000 | E18: 10000000 | F18: 10000000 | G18: =sum(C18:F18) -> 40000000 | H18: =VLOOKUP(A18,Dashboard!A:G,7,FALSE) -> 480000000
A19: 77394861 | B19: Ngacai | C19: 1840000 | D19: 1840000 | E19: 2760000 | F19: 2760000 | G19: =sum(C19:F19) -> 9200000 | H19: =VLOOKUP(A19,Dashboard!A:G,7,FALSE) -> 64400000
A20: 146428825 | B20: ᵐᵖ Ray i | C20: 2005600 | D20: 2014400 | E20: 2990000 | F20: 2990000 | G20: =sum(C20:F20) -> 10000000 | H20: =VLOOKUP(A20,Dashboard!A:G,7,FALSE) -> 69320400
A21: 171604682 | B21: Łørd Ᵽraмa | C21: 2576000 | D21: 2576000 | E21: 2576000 | F21: 2272000 | G21: =sum(C21:F21) -> 10000000 | H21: =VLOOKUP(A21,Dashboard!A:G,7,FALSE) -> 210800000
A22: 169446444 | B22: lazy Liwen 寳 | C22: 2003760 | D22: 2003760 | E22: 3082000 | F22: 2910480 | G22: =sum(C22:F22) -> 10000000 | H22: =VLOOKUP(A22,Dashboard!A:G,7,FALSE) -> 62400224
A23: 156339380 | B23: 會 ᴋᴀʏ シ | C23: 10000000 | D23: 10000000 | E23: 10000000 | F23: 10000000 | G23: =sum(C23:F23) -> 40000000 | H23: =VLOOKUP(A23,Dashboard!A:G,7,FALSE) -> 280000000
A24: =count(Week_16_22_Feb_2026[ID]) & " Contributors" -> 20 Contributors | C24: =sum(Week_16_22_Feb_2026[Food]) -> 126549360 | D24: =sum(Week_16_22_Feb_2026[Wood]) -> 161838160 | E24: =sum(Week_16_22_Feb_2026[Stone]) -> 94132000 | F24: =sum(Week_16_22_Feb_2026[Gold]) -> 70712480 | G24: =sum(Week_16_22_Feb_2026[Week Contribution]) -> 453232000 | H24: =sum(Week_16_22_Feb_2026[Total Contribution]) -> 5160290376
A31: ID | B31: Name | C31: Food | D31: Wood | E31: Stone | F31: Gold | G31: Week Contribution | H31: Total Contribution
A32: 176044158 | B32: メSuper Manメ | C32: 10000000 | D32: 10000000 | E32: 10000000 | F32: 10000000 | G32: =sum(C32:F32) -> 40000000 | H32: =VLOOKUP(A32,Dashboard!A:G,7,FALSE) -> 480000000
A33: 172033754 | B33: Dreckschlumpf | C33: 2760000 | D33: 91720000 | E33: 2760000 | F33: 2760000 | G33: =sum(C33:F33) -> 100000000 | H33: =VLOOKUP(A33,Dashboard!A:G,7,FALSE) -> 930794163
A34: 169427770 | B34: SAX0N | C34: 2760000 | D34: 123680000 | E34: 2640000 | F34: 920000 | G34: =sum(C34:F34) -> 130000000 | H34: =VLOOKUP(A34,Dashboard!A:G,7,FALSE) -> 278400000
A35: 167614515 | B35: ᵂʷ Jools シ | C35: 1840000 | D35: 3680000 | E35: 1840000 | F35: 1840000 | G35: =sum(C35:F35) -> 9200000 | H35: =VLOOKUP(A35,Dashboard!A:G,7,FALSE) -> 73600000
A36: 171503078 | B36: メCalメ | C36: 30000000 | D36: 1840000 | E36: 1840000 | F36: 1840000 | G36: =sum(C36:F36) -> 35520000 | H36: =VLOOKUP(A36,Dashboard!A:G,7,FALSE) -> 390959600
A37: 64966340 | B37: Pisontije | C37: 10000000 | D37: 10000000 | E37: 10000000 | F37: 10000000 | G37: =sum(C37:F37) -> 40000000 | H37: =VLOOKUP(A37,Dashboard!A:G,7,FALSE) -> 184600000
A38: 171604682 | B38: Ᵽraмa | C38: 5152000 | D38: 5152000 | E38: 5464000 | F38: 4232000 | G38: =sum(C38:F38) -> 20000000 | H38: =VLOOKUP(A38,Dashboard!A:G,7,FALSE) -> 210800000
A39: 62576249 | B39: ﾒUğurﾒ | E39: 10000000 | G39: =sum(C39:F39) -> 10000000 | H39: =VLOOKUP(A39,Dashboard!A:G,7,FALSE) -> 240000000
A40: 171972257 | B40: Steelite | C40: 20000000 | G40: =sum(C40:F40) -> 20000000 | H40: =VLOOKUP(A40,Dashboard!A:G,7,FALSE) -> 163000000
A41: 98107237 | B41: 亗 Intersect | C41: 20000000 | G41: =sum(C41:F41) -> 20000000 | H41: =VLOOKUP(A41,Dashboard!A:G,7,FALSE) -> 330000000
A42: 171879011 | B42: Urkel94 | C42: 10000000 | D42: 10000000 | E42: 10000000 | F42: 10000000 | G42: =sum(C42:F42) -> 40000000 | H42: =VLOOKUP(A42,Dashboard!A:G,7,FALSE) -> 559999998
A43: 156339380 | B43: 會 ᴋᴀʏ シ | C43: 10000000 | D43: 10000000 | E43: 10000000 | F43: 10000000 | G43: =sum(C43:F43) -> 40000000 | H43: =VLOOKUP(A43,Dashboard!A:G,7,FALSE) -> 280000000
A44: 168455139 | B44: ᵁᴺOdin | C44: 10000000 | D44: 10000000 | E44: 10000000 | F44: 10000000 | G44: =sum(C44:F44) -> 40000000 | H44: =VLOOKUP(A44,Dashboard!A:G,7,FALSE) -> 1510000000
A45: 169446444 | B45: lazy Liwen 寳 | C45: 6000056 | D45: 6000056 | E45: 6000056 | F45: 6000056 | G45: =sum(C45:F45) -> 24000224 | H45: =VLOOKUP(A45,Dashboard!A:G,7,FALSE) -> 62400224
A46: 146428825 | B46: ᵐᵖ Ray i | C46: 2039640 | D46: 2041080 | E46: 2959640 | F46: 2959640 | G46: =sum(C46:F46) -> 10000000 | H46: =VLOOKUP(A46,Dashboard!A:G,7,FALSE) -> 69320400
A47: 11726598 | B47: Lazy Cat ツ | C47: 30000000 | G47: =sum(C47:F47) -> 30000000 | H47: =VLOOKUP(A47,Dashboard!A:G,7,FALSE) -> 68280001
A48: 168091444 | B48: ᵁᴺOhanaツ | C48: 3680000 | D48: 3680000 | E48: 5520000 | F48: 5520000 | G48: =sum(C48:F48) -> 18400000 | H48: =VLOOKUP(A48,Dashboard!A:G,7,FALSE) -> 235864000
...

Sheet Contributors Log
A1: ID | B1: Player | C1: Alliance | D1: Expected Weekly | E1: Received This Week? | F1: Last Received | G1: Notes
A2: 2463403 | B2: Heliøsツ | C2: U97 | D2: 40M RSS | E2: FALSE
A3: 11726598 | B3: Lazy Cat ツ | C3: U97 | D3: 40M RSS | E3: FALSE
A4: 64966340 | B4: Pisontije | C4: U97 | D4: 40M RSS | E4: TRUE
A5: 171604682 | B5: Łørd Ᵽraмa | ᵁᴺDaddyツ | C5: U97 | D5: 40M RSS | E5: TRUE
A6: 67071592 | B6: 乄Lazy Bツ | C6: U97 | D6: 40M RSS | E6: FALSE
A7: 169326547 | B7: ᵁᴺSexyRickツ | C7: U97 | D7: 40M RSS | E7: FALSE
A8: 156339380 | B8: 會 ᴋᴀʏ シ | C8: U97 | D8: 40M RSS | E8: TRUE
A9: 167637163 | B9: ・Maka・ | C9: U97 | D9: 40M RSS | E9: TRUE
A10: 169446444 | B10: lazy Liwen 寳 | C10: U97 | D10: 40M RSS | E10: TRUE
A11: 169461237 | B11: Aurionツ | C11: U97 | D11: 40M RSS | E11: TRUE
A12: 145408006 | B12: Adam23 | C12: U97 | D12: 20M RSS | E12: FALSE
A13: 63222201 | B13: AmiralMaximus | C13: U97 | D13: 20M RSS | E13: FALSE
... A107: 136662717 | B107: PickleShadowツ | C107: U97 | D107: 20M RSS | E107: FALSE
A110: Week 9 Feb- 15 Feb 2026 Non Contributors
A112: ID | B112: Name
A113: 145408006 | B113: Adam23
A114: 63222201 | B114: AmiralMaximus
A115: 64010776 | B115: ᵀᶜ Tequila
A116: 171934536 | B116: FromKiev1122
A117: 62691192 | B117: Siyempi
A118: 71152824 | B118: FIREWoLF
A119: 11409556 | B119: Enes 33
A120: 14572491 | B120: LAZY BOOND
A121: 171827401 | B121: King ᶠʳʸ
A122: 140009179 | B122: Herakles ツ
A123: 144049878 | B123: Losant
A124: 166871338 | B124: ᴴᵘⁿBéo
... A168: 79650085 | B168: Keshiba ツ
A170: Week 2 Feb- 8 Feb 2026 Non Contributors
A172: ID | B172: Name
A173: 171604682 | B173: Łørd Ᵽraмa | ᵁᴺDaddyツ
A174: 169326547 | B174: ᵁᴺSexyRickツ
A175: 169446444 | B175: lazy Liwen 寳
A176: 145408006 | B176: Adam23
A177: 63222201 | B177: AmiralMaximus
A178: 64010776 | B178: ᵀᶜ Tequila
A179: 115125159 | B179: ᵂAᴿ Demon
A180: 62691192 | B180: Siyempi
A181: 144060837 | B181: 义CHRYS义
...

Sheet Penalty Ledger
A1: Player | B1: Reason | C1: Fine Amount (F/W/S/G) | D1: Paid? | E1: Date Due | F1: Notes
A2: Adam23 | B2: AM Abuse | C2: 59.5M / 59.5M / 59.5M / 59.5M | D2: No | E2: 45886 | F2: 238M paid 50M
A3: ᴱᴿ RKing79 | B3: AM Abuse | C3: 51.5M / 51.5M / 51.5M / 51.5M | D3: Yes | E3: 45886 | F3: PAID 194,720,000 (206M)
A4: sd mique | B4: AM Abuse | C4: 42.8M / 42.8M / 42.8M / 42.8M | D4: Yes | E4: 45886 | F4: 171.2M Paid (166,586,560M)
A5: Mictlan Tecutli | B5: AM Abuse | C5: 31.6M / 31.6M / 31.6M / 31.6M | D5: Yes | E5: 45886 | F5: 126.4M Lord Valkorion PAID
A6: 乄Muhtarツ | B6: AM Abuse | C6: 13.6M / 13.6M / 13.6M / 13.6M | D6: Yes | E6: 45886 | F6: 54.4M
A7: СЕНАТОР | B7: AM Abuse | C7: 12.6M / 12.6M / 12.6M / 12.6M | D7: Yes | E7: 45886 | F7: 50.4M
A8: ᵀᵒKinfernus | B8: AM Abuse | C8: 12.4M / 12.4M / 12.4M / 12.4M | D8: Yes | E8: 45886 | F8: 49.6M (30/8 110M)
A9: DEHA DEVRAN | B9: AM Abuse | C9: 10.6M / 10.6M / 10.6M / 10.6M | D9: Yes | E9: 45886 | F9: 42.4M
A10: roimme | B10: AM Abuse | C10: 6.1M / 6.1M / 6.1M / 6.1M | D10: Yes | E10: 45886 | F10: 24.4M
A11: TitanMARU | B11: AM Abuse | C11: 3.3M / 3.3M / 3.3M / 3.3M | D11: Yes | E11: 45886 | F11: 13.2M
A12: yamen Di | B12: AM Abuse | C12: 0.5M / 0.5M / 0.5M / 0.5M | D12: Yes | E12: 45886 | F12: 2M
A13: Fabregas1533 | B13: AM Abuse | C13: 0.1M / 0.1M / 0.1M / 0.1M | D13: Yes | E13: 45886 | F13: 0.4M
... A16: Heliøsツ | B16: MGE Abuse | C16: 15M/ 15M/ 15M/ 15M | D16: Yes | E16: 45890 | F16: (60M)
A17: Grimm48 | B17: GH Abuse | C17: 10M/ 10M/ 10M/ 10M | D17: Yes | E17: 45892
A18: ᵂᴸSnowWoLF | B18: GH Abuse | C18: 20M/ 10M/ 15.5M/ 10M | D18: Yes | E18: 45893
A19: MƏGÁN | B19: Low Activity | C19: 87.5M/ 87.5M/ 87.5M/ 87.5M | D19: No | F19: 350M RSS (25/8 PAID 230M)
A20: V for VENDETTA | B20: Low Activity | C20: 125M/ 125M/ 125M/ 125M | D20: No | F20: 500M RSS (25/8 PAID 82.8M | 29/8 73.6M | 14/9 73.6M (230M))
A21: DEHA DEVRAN | БОБОО79 | B21: GH Abuse | C21: 242.1M/ 219.6M/ 260M/ 217.9M | D21: Yes | F21: 1B (Paid 939.7M)
A22: R7R7 | B22: GH Abuse | C22: 150M/ 1B / 140M/ 70M | D22: Yes | F22: 1.4B
A23: sd mique | B23: GH Abuse | C23: 178M/ 134.7M/ 133.2M/ 160.5M | D23: No | F23: 2B (Paid 6/9 606.6M)
A24: J Pangestu | B24: GH Abuse | D24: No
A25: Lord Valkorion | B25: GH Abuse | C25: 200M/ 50M/ 200M/ 50M | D25: Yes | F25: 500M
A26: 亗DJ KAMA亗 | B26: GH Abuse | D26: No | F26: 1.2B
A27: atom karica | B27: AM Abuse | C27: 100M/ 100M/ 100M/ 100M | D27: No | E27: 45922 | F27: 400M
A28: MƏGÁN | B28: AM Abuse | C28: 83.5M/ 83.5M/ 83.5M/ 83.5M | D28: No | E28: 45922 | F28: 334M
A29: EspDido | B29: AM Abuse | C29: 71.8M/ 71.8M/ 71.8M/ 71.8M | D29: No | E29: 45922 | F29: 287.2M
A30: FallenRooti8 | B30: AM Abuse | C30: 65M/ 65M/ 65M/ 65M | D30: No | E30: 45922 | F30: 260M
A31: Mofu1 | B31: AM Abuse | C31: 28.3M/ 28.3M/ 28.3M/ 28.3M | D31: No | E31: 45922 | F31: 113.2M
A32: Fabregas1533 | B32: AM Abuse | C32: 22M/ 22M/ 22M/ 22M | D32: Yes | E32: 45922 | F32: 88M
A33: 亗 BatMank 亗 | B33: AM Abuse | C33: 32.7M/ 32.7M/ 32.7M/ 32.7M | D33: No | E33: 45950 | F33: 130.8M 17/10 -50M
A34: Vega13 | B34: AM Abuse | C34: 20.2M/ 20.2M/ 20.2M/ 20.2M | D34: Yes | E34: 45950 | F34: 80.8M
A35: Melottus | B35: AM Abuse | C35: 2M/ 2M/ 2M/ 2M | D35: Yes | E35: 45950 | F35: 8M
A36: RiP2016 | B36: MGE Abuse | C36: 600M G | D36: Yes | E36: 45974 | F36: 10/11: 530.4M
A37: ᵂᴸSnowWoLF | B37: GH Abuse | C37: 1.225B | D37: Pardon | E37: 46055 | F37: 27/1 390M | Total: 390M
A38: Lazy Cat ツ | B38: GH Abuse | C38: 1.220B | D38: Pardon | E38: 46055
A39: Adam23 | B39: GH Abuse | C39: 1.043B | D39: No | E39: 46055
A40: ᵁᴺOdin | B40: GH Abuse | C40: 1.012B | D40: Yes | E40: 46055
A41: Luki92 | B41: GH Abuse | C41: 845M | D41: Yes | E41: 46055
A42: RiP2016 | B42: GH Abuse | C42: 456M | D42: Yes | E42: 46055 | F42: 1/2 172M | 31/1 292M | Total: 464M
...

Sheet Withdrawals Log
A1: Date | B1: Recipient | C1: Purpose | D1: Food | E1: Wood | F1: Stone | G1: Gold | H1: Approved By | I1: Notes
A2: 45926 | B2: Lord Valkorion | C2: Fight | D2: 0 | E2: 0 | F2: 0 | G2: 200000000 | H2: Helios
A3: 45944 | B3: 乄Lazy Bツ | C3: Fight | D3: 400000000 | E3: 400000000 | F3: 400000000 | G3: 400000000 | H3: Kay
A4: 45947 | B4: FIREWoLF | C4: Fight | F4: 400000000 | H4: Kay
A5: 45947 | B5: ᵂᴸSnowWoLF | C5: Fight | E5: 400000000 | G5: 200000000 | H5: Kay
A6: 45948 | B6: 乄Lazy Bツ | C6: Fight | D6: 1000000000 | E6: 1000000000 | G6: 800000000 | H6: Kay
A7: 45948 | B7: Heliøsツ | C7: Fight | D7: 500000000 | E7: 500000000 | G7: 500000000 | H7: Helios
A8: 45954 | B8: Dreckschlumpf | C8: Fight | G8: 20000000 | H8: Helios
A9: 46001 | B9: Keshiba ツ | C9: Fight | D9: 300000000 | E9: 1000000000 | F9: 1000000000 | G9: 300000000 | H9: Helios
A10: 46005 | B10: Luki92 | C10: Fight | F10: 800000000 | G10: 500000000 | H10: Kay
A11: 46014 | B11: ᵁᴺSexyRickツ | C11: Fight | G11: 500000000 | H11: Kay
A12: 46018 | B12: ᵁᴺSexyRickツ | C12: Fight | D12: 500000000 | E12: 1500000000 | H12: Kay
A13: 46019 | B13: Luki92 | C13: Fight | F13: 800000000 | G13: 200000000 | H13: Kay
A14: 46020 | B14: 乄Lazy Bツ | C14: Fight | D14: 1000000000 | E14: 1000000000 | F14: 1000000000 | G14: 800000000 | H14: Kay
A15: 46021 | B15: ᵁᴺPraMaツ | C15: Fight | D15: 400000000 | E15: 600000000 | G15: 250000000 | H15: Helios
A16: 46021 | B16: メCalメ | C16: Fight | E16: 800000000 | H16: Kay
A17: 46025 | B17: ᵂᴸSnowWoLF | C17: Fight | E17: 800000000 | G17: 100000000 | H17: Kay
A18: 46026 | B18: 乄Lazy Bツ | C18: Fight | D18: 800000000 | E18: 500000000 | F18: 800000000 | G18: 100000000 | H18: Kay
A19: 46028 | B19: 乄Narcissus | C19: Fight | D19: 800000000 | E19: 800000000 | F19: 800000000 | G19: 200000000 | H19: Helios
A20: 46028 | B20: madelene | C20: Fight | D20: 100000000 | F20: 100000000 | H20: Kay
A21: 46032 | B21: Luki92 | C21: Fight | F21: 500000000 | H21: Kay
A22: 46032 | B22: ᵁᴺPraMaツ | C22: Fight | E22: 650000000 | G22: 100000000 | H22: Kay
A23: 46032 | B23: SAX0N | C23: Fight | D23: 500000000 | G23: 50000000 | H23: Kay
